Workbook

Sheet İŞLETME KAYIT NO
B1: ALINMA TARİHİ | C1: TEDARİK | D1: ÜRÜN | E1: MENŞEİ | F1: T.E.T.T./S.K.T. | G1: İŞLETME KAYIT NO | H1: FİRMA ADI | I1: ADRESİ
B2: 45950 | C2: TÜDAB | D2: MEBRUM HURMA (MEDİNE HURMA DUBLE) | E2: SUUDİ ARABİSTAN | F2: 45837 | G2: TR-34-K-144663 | H2: ANADOLU KURUYEMİŞ VE GIDA PAZ. LTD. | I2: MAHMUTBEY MH. İSTOÇ 22. YOL 21. ADA NO:2 BAĞCILAR/İSTANBUL
B3: 45950 | C3: TÜDAB | D3: MEDJOOL HURMA - (KUDÜS HURMASI JUMBO) | E3: ? | F3: ? | H3: SOUTHERNCROSS | I3: GÜNEY AFRİKA
B4: 45950 | C4: TÜDAB | D4: KAVRULMUŞ BADEM | E4: ? | F4: ? | G4: TÜDAB?
B5: 45950 | C5: TÜDAB | D5: FINDIK İÇİ KAVRULMUŞ (FINDIK BULANCAK) | E5: TÜRKİYE | F5: 46646 | G5: TR-34-K-138502 | H5: TÜDAB GIDA SAN.TİC. A.Ş. | I5: İSTOÇ TİCARET MRK. 19 . ADA NO:108-114 BAĞCILAR İSTANBUL
B6: 45950 | C6: TÜDAB | D6: LEBLEBİ ŞEKERİ | E6: TÜRKİYE | F6: 46115 | G6: TR-20-K-021980 | H6: GENÇ KURUYEMİŞ LTD. ŞİT. | I6: AŞAĞI MH. 3007 SK. 7. BLOK NO:2-8 C SERİNHİSAR - DENİZLİ
B7: 45950 | C7: TÜDAB | D7: SARI LEBLEBİ | E7: TÜRKİYE | F7: 46274 | G7: TR-43-K-011401 | H7: KORKMAZLAR GIDA VE TAŞIMACILIK A.Ş. | I7: ÇUKURKÖY MAH. LEBLEBİCİLER SANAYİ KÜME EVLERİ NO:2 TAVŞANLI- KÜTAHYA
B8: 45950 | C8: TÜDAB | D8: KURU ÜZÜM | E8: TÜRKİYE | F8: 46266 | G8: TR-45-K-021984 | H8: UFUK ŞENGÜN TARIM ÜRÜNLERİ İÇ VE DIŞ TİC. SANAYİ LTD | I8: Koldere Mahallesi Cengiz Ergün Cd, A Blok Sk. No:4/1, Saruhanlı/Manisa
B9: 45950 | C9: TÜDAB | D9: ÇITIR LEBLEBİ | E9: TÜRKİYE | F9: 46260 | G9: TR-20-K-002161 | H9: GENÇ KURUYEMİŞ LTD. ŞİT. | I9: AŞAĞI MH. 3007 SK. 7. BLOK NO:2-8 C SERİNHİSAR - DENİZLİ
B10: 45950 | C10: TÜDAB | D10: BADEM | E10: TÜRKİYE | F10: 46099 | G10: TR-34-K-014403 | H10: ÇAMDALI KURUYEMİŞ | I10: MERKEZ MH. YEŞİL ZÜMRÜT SK. NO:27 G.O. PAŞA/İSTANBUL
B11: 45950 | C11: TÜDAB | D11: KAVRULMUŞ KABUKLU ANTEP FISTIK | E11: TÜRKİYE | F11: 46266 | G11: TR-27-K-005728 | H11: DEMKAR NUTS GIDA LTD. ŞTİ. | I11: Burak Mah. 0617 Nolu Cad. No:24 Şehitkamil/Gaziantep
B12: 45950 | C12: TÜDAB | D12: DERME KURU KAYISI - JUMBO | E12: TÜRKİYE | F12: 46268 | G12: TR-44-K-000490 | H12: BİRDEM GIDA SAN. TİC. A.Ş. | I12: 1. OSB MAH. 13. CAD. NO:8 YEŞİLYURT/MALATYA
B13: 45950 | C13: TÜDAB | D13: KURU İNCİR | E13: TÜRKİYE | F13: 46266 | G13: ? | H13: NBN 2,5 KG İNCİR ? | I13: ?
B14: 45950 | C14: TÜDAB | D14: DAĞ İNCİRİ | F14: 46266 | G14: TR-09-K-030024 | H14: KUDA ORGANİK | I14: MESUDİYE MAHALLESİ ATATÜRK CD. NO:90 GERMENCİK / AYDIN
B15: 45950 | C15: TÜDAB | D15: HİMALAYA TUZU | E15: ? | F15: ? | G15: TR34-K-138502 | H15: TÜDAB GIDA SAN.TİC. A.Ş. | I15: İSTOÇ TİCARET MRK. 19 . ADA NO:108-114 BAĞCILAR İSTANBUL
B16: 45950 | C16: TÜDAB | D16: PAPATYA | E16: TÜRKİYE | F16: 46589 | G16: TR-34-K-138502 | H16: TÜDAB GIDA SAN.TİC. A.Ş. | I16: İSTOÇ TİCARET MRK. 19 . ADA NO:108-114 BAĞCILAR İSTANBUL
B17: 45950 | C17: TÜDAB | D17: KARANFİL | E17: ENDONEZYA | F17: 46667 | G17: TR-34-K-138502 | H17: TÜDAB GIDA SAN.TİC. A.Ş. | I17: İSTOÇ TİCARET MRK. 19 . ADA NO:108-114 BAĞCILAR İSTANBUL
B18: 45961 | C18: TÜDAB | D18: TOZ BİBER - TATLI | E18: TÜRKİYE | F18: 46689 | G18: TR-27-K-001589 | H18: YALÇINKAYA BİBER BAHARAT LTD. | I18: ERENLER MAH. GAZİANTEP BULVARI NO:125 İSLAHİYE / GAZİANTEP
B19: 45950 | C19: TÜDAB | D19: FINDIK İÇİ ÇİĞ | E19: TÜRKİYE | F19: 46540 | G19: TR-34-K-138502 | H19: TÜDAB GIDA SAN.TİC. A.Ş. | I19: İSTOÇ TİCARET MRK. 19 . ADA NO:108-114 BAĞCILAR İSTANBUL
B20: 45966 | C20: TÜDAB | D20: TÜDAB TURŞU 4.500 GR | E20: TÜRKİYE | F20: 46661 | G20: TR-34-K-138502 | H20: TÜDAB GIDA SAN.TİC. A.Ş. | I20: İSTOÇ TİCARET MRK. 19 . ADA NO:108-114 BAĞCILAR İSTANBUL
B21: 45973 | C21: TÜDAB | D21: LEBLEBİ ŞEKERİ - REKLİ | E21: TÜRKİYE | F21: 46211 | G21: TR-20-K-021980 | H21: GENÇ KURUYEMİŞ LTD. ŞİT. | I21: AŞAĞI MH. 3007 SK. 7. BLOK NO:2-8 C SERİNHİSAR - DENİZLİ
B22: 45973 | C22: TÜDAB | D22: KABAK ÇEKİRDEĞİ - NEVŞEHİR | E22: TÜRKİYE | F22: 46045 | G22: TR-34-K-138502 | H22: TÜDAB GIDA SAN.TİC. A.Ş. | I22: İSTOÇ TİCARET MRK. 19 . ADA NO:108-114 BAĞCILAR İSTANBUL
B23: 45973 | C23: TÜDAB | D23: CEVİZLİ SUCUK ATOM (ESMER) | E23: TÜRKİYE | F23: 46116 | G23: TR-46-K-015522 | H23: SAVAŞ ABAKAY GIDA LTD. | I23: KARACASU KARAZİYARET MAH. 81004. SK. NO:10/B DULKADİROĞLU/K.MARAŞ
B24: 45973 | C24: TÜDAB | D24: TUZSUZ FISTIK 1 NO | E24: TÜRKİYE | F24: 46207 | G24: TR-34-K-135574 | H24: ER SA GIDA KURUYEMİŞ | I24: İKİTELLİ OSB SEFAKÖY SAN. SİT. 16. BLOK NOç15/16 BAŞAKŞEHİR/İSTANBUL
B25: 45973 | C25: TÜDAB | D25: TUZLU FISTIK DUBLE | E25: TÜRKİYE | F25: 46302 | G25: TR-34-K-135574 | H25: ER SA GIDA KURUYEMİŞ | I25: İKİTELLİ OSB SEFAKÖY SAN. SİT. 16. BLOK NOç15/16 BAŞAKŞEHİR/İSTANBUL
B26: 45971 | C26: TÜDAB | D26: GENÇLEBİ ÇAKILTAŞI DRAJE | E26: TÜRKİYE | F26: 46256 | G26: TR-20-K-001833 | H26: GENÇ KURUYEMİŞ LTD. ŞİT. | I26: AŞAĞI MH. 3007 SK. 7. BLOK NO:2-8 C SERİNHİSAR - DENİZLİ
B27: 45971 | C27: TÜDAB | D27: KAJU 240 LIK EKSTRA | E27: TÜRKİYE | F27: 46126 | G27: TR-34-K-089145 | H27: MNA NUT KURUYEMİŞÇİLİK LTD. | I27: KOCATEPE MAH. MEGA CENTER GIDA SİTESİ C-7 BLOK NO:57 BAYRAMPAŞA / İST
... B29: 45950 | C29: TÜDAB | D29: BİBERİYE | E29: TÜRKİYE | F29: 46559 | G29: TR-34-K-138502 | H29: TÜDAB GIDA SAN.TİC. A.Ş. | I29: İSTOÇ TİCARET MRK. 19 . ADA NO:108-114 BAĞCILAR İSTANBUL
B30: 45950 | C30: TÜDAB | D30: AÇLIK OTU | E30: TÜRKİYE | F30: ? | G30: ? | H30: ? | I30: ?
B31: 45971 | C31: TÜDAB | D31: YEŞİL ÇAY YAPRAK | E31: ÇİN | F31: 46631 | G31: TR-34-K-138502 | H31: TÜDAB GIDA SAN.TİC. A.Ş. | I31: İSTOÇ TİCARET MRK. 19 . ADA NO:108-114 BAĞCILAR İSTANBUL
B32: 45950 | C32: TÜDAB | D32: HAYIT TOHUMU | E32: TÜRKİYE | F32: 46645 | G32: TR-34-K-138502 | H32: TÜDAB GIDA SAN.TİC. A.Ş. | I32: İSTOÇ TİCARET MRK. 19 . ADA NO:108-114 BAĞCILAR İSTANBUL
B33: 45978 | C33: TÜDAB | D33: KUŞBURNU - KIRMIZI | E33: TÜRKİYE | F33: 46692 | G33: TR-34-K-138502 | H33: TÜDAB GIDA SAN.TİC. A.Ş. | I33: İSTOÇ TİCARET MRK. 19 . ADA NO:108-114 BAĞCILAR İSTANBUL
B34: 45950 | C34: TÜDAB | D34: ASLAN PENÇESİ | E34: TÜRKİYE | F34: 46114 | G34: TR-34-K-138502 | H34: TÜDAB GIDA SAN.TİC. A.Ş. | I34: İSTOÇ TİCARET MRK. 19 . ADA NO:108-114 BAĞCILAR İSTANBUL
B35: 45950 | C35: TÜDAB | D35: LİMON MELİSA | E35: SURİYE | F35: 46523 | G35: TR-34-K-138502 | H35: TÜDAB GIDA SAN.TİC. A.Ş. | I35: İSTOÇ TİCARET MRK. 19 . ADA NO:108-114 BAĞCILAR İSTANBUL
B36: 45950 | C36: TÜDAB | D36: KIRKLİLİT OTU | E36: TÜRKİYE | F36: 46657 | G36: TR-34-K-138502 | H36: TÜDAB GIDA SAN.TİC. A.Ş. | I36: İSTOÇ TİCARET MRK. 19 . ADA NO:108-114 BAĞCILAR İSTANBUL
B37: 45950 | C37: TÜDAB | D37: ZEYTİN YAPĞRAĞI | E37: ? | F37: ? | G37: TR-34-K-138502 | H37: TÜDAB GIDA SAN.TİC. A.Ş. | I37: İSTOÇ TİCARET MRK. 19 . ADA NO:108-114 BAĞCILAR İSTANBUL
B38: 45950 | C38: TÜDAB | D38: ADAÇAYI SIYIRMA | E38: ? | F38: ? | G38: TR-34-K-138502 | H38: TÜDAB GIDA SAN.TİC. A.Ş. | I38: İSTOÇ TİCARET MRK. 19 . ADA NO:108-114 BAĞCILAR İSTANBUL
B39: 45950 | C39: TÜDAB | D39: KİRAZ SAPI | E39: ? | F39: ? | G39: TR-34-K-138502 | H39: TÜDAB GIDA SAN.TİC. A.Ş. | I39: İSTOÇ TİCARET MRK. 19 . ADA NO:108-114 BAĞCILAR İSTANBUL
B40: 45989 | C40: TÜDAB | D40: KÖFTELİK BULGUR | E40: TÜRKİYE | F40: 46354 | G40: TR-34-K-138502 | H40: TÜDAB GIDA SAN.TİC. A.Ş. | I40: İSTOÇ TİCARET MRK. 19 . ADA NO:108-114 BAĞCILAR İSTANBUL
B41: 45990 | C41: TÜDAB | D41: BİLAVLIK BULGUR | E41: TÜRKİYE | F41: 46354 | G41: TR-34-K-138502 | H41: TÜDAB GIDA SAN.TİC. A.Ş. | I41: İSTOÇ TİCARET MRK. 19 . ADA NO:108-114 BAĞCILAR İSTANBUL
...

Sheet CARİ KARTLARI
A1: K.KODU | B1: İSMİ
B2: TÜDAB A.Ş.
B3: YALÇINTAT BAHARAT GIDA LTD.
B4: HARUN ADANA
B5: MEHMET DAŞDEMİR - K.K.
B6: GENÇAY BAHARAT - İSMAİL MAHMUT GENÇAY
B7: TFK-POS
B8: MUHTELİF MÜŞTERİ
B9: GE-MA GIDA TİCARET LTD.ŞTİ.
B10: SERBEND HURMA
B11: ORHAN ABLAK HOCA
B12: EL-RUHA ÇAY
B13: SERMAYE
... B31: ERASLAN LAHMACUN PİDE

Sheet HİZMET KARTLARI
A1: K.KODU | B1: CİNSİ
B2: TEMİZLİK GİDERLERİ
B3: MUTFAK GİDERLERİ
B4: BİNA BAKIM ONARIM
B5: DEMİRBAŞ
B6: YOL GİDERLERİ
B7: KİRA GİDERLERİ
B8: DEPOZİTO GİDERLERİ
B9: DIŞARIDAN SAĞLANAN FAYDA VE HİZMETLER
B10: GİDER SAYILAN DEMİRBAŞ
B11: AMBALAJ GİDERLERİ
B12: MUHASEBE GİDERLERİ
B13: İSKONTO GİDERLERİ
... B21: FİRE GİDERLERİ

Sheet STOK KARTLARI
A1: S.KODU | B1: SATIŞ TÜRÜ | C1: CİNSİ | D1: MİKTAR | E1: BİRİM | F1: FİYAT | G1: TUTAR | H1: Sütun2 | I1: SATIŞ FİYATI | J1: YUVARLAMA | K1: firma | L1: FARK | M1: YUVARLAMA
A2: BAHARAT | B2: KİLO | C2: KARABİBER ÇEKİLMİŞ | D2: 25 | E2: KG | F2: 320 | G2: 8000 | H2: 2 | I2: =Table001__Page_15[[#This Row],[FİYAT]]*Table001__Page_15[[#This Row],[Sütun2]] -> 640 | J2: 650 | K2: antep | L2: =Table001__Page_15[[#This Row],[SATIŞ FİYATI]]-Table001__Page_15[[#This Row],[YUVARLAMA]] -> -10 | M2: 650 | N2: =M2-Table001__Page_15[[#This Row],[YUVARLAMA]] -> 0
A3: BAHARAT | B3: KİLO | C3: KİMYON ÇEKİLMİŞ | D3: 25 | E3: KG | F3: 170 | G3: 4250 | H3: 2.4 | I3: =Table001__Page_15[[#This Row],[FİYAT]]*Table001__Page_15[[#This Row],[Sütun2]] -> 408 | J3: 400 | K3: antep | L3: =Table001__Page_15[[#This Row],[SATIŞ FİYATI]]-Table001__Page_15[[#This Row],[YUVARLAMA]] -> 8 | M3: 400 | N3: =M3-Table001__Page_15[[#This Row],[YUVARLAMA]] -> 0
A4: BAHARAT | B4: KİLO | C4: KÖFTE BAHARATI (YEDİTÜRLÜ) | D4: 10 | E4: KG | F4: 180 | G4: 1800 | H4: 2.3 | I4: =Table001__Page_15[[#This Row],[FİYAT]]*Table001__Page_15[[#This Row],[Sütun2]] -> 414 | J4: 450 | K4: antep | L4: =Table001__Page_15[[#This Row],[SATIŞ FİYATI]]-Table001__Page_15[[#This Row],[YUVARLAMA]] -> -36 | M4: 450 | N4: =M4-Table001__Page_15[[#This Row],[YUVARLAMA]] -> 0
A5: BAHARAT | B5: KİLO | C5: NANE İRİ | D5: 25 | E5: KG | F5: 125 | G5: 3125 | H5: 3.2 | I5: =Table001__Page_15[[#This Row],[FİYAT]]*Table001__Page_15[[#This Row],[Sütun2]] -> 400 | J5: 400 | K5: antep | L5: =Table001__Page_15[[#This Row],[SATIŞ FİYATI]]-Table001__Page_15[[#This Row],[YUVARLAMA]] -> 0 | M5: 400 | N5: =M5-Table001__Page_15[[#This Row],[YUVARLAMA]] -> 0
A6: BAHARAT | B6: KİLO | C6: SUMAK | D6: 25 | E6: KG | F6: 200 | G6: 5000 | H6: 2.5 | I6: =Table001__Page_15[[#This Row],[FİYAT]]*Table001__Page_15[[#This Row],[Sütun2]] -> 500 | J6: 500 | K6: antep | L6: =Table001__Page_15[[#This Row],[SATIŞ FİYATI]]-Table001__Page_15[[#This Row],[YUVARLAMA]] -> 0 | M6: 500 | N6: =M6-Table001__Page_15[[#This Row],[YUVARLAMA]] -> 0
A7: BAHARAT | B7: KİLO | C7: KEKİK LÜX | D7: 10 | E7: KG | F7: 420 | G7: 4200 | H7: 2 | I7: =Table001__Page_15[[#This Row],[FİYAT]]*Table001__Page_15[[#This Row],[Sütun2]] -> 840 | J7: 850 | K7: antep | L7: =Table001__Page_15[[#This Row],[SATIŞ FİYATI]]-Table001__Page_15[[#This Row],[YUVARLAMA]] -> -10 | M7: 850 | N7: =M7-Table001__Page_15[[#This Row],[YUVARLAMA]] -> 0
A8: BAHARAT | B8: KİLO | C8: İPEK BİBER | D8: 25 | E8: KG | F8: 250 | G8: 6250 | H8: 2 | I8: =Table001__Page_15[[#This Row],[FİYAT]]*Table001__Page_15[[#This Row],[Sütun2]] -> 500 | J8: 500 | K8: antep | L8: =Table001__Page_15[[#This Row],[SATIŞ FİYATI]]-Table001__Page_15[[#This Row],[YUVARLAMA]] -> 0 | M8: 500 | N8: =M8-Table001__Page_15[[#This Row],[YUVARLAMA]] -> 0
A9: BAHARAT | B9: KİLO | C9: İSOT | D9: 25 | E9: KG | F9: 180 | G9: 4500 | H9: 2.2 | I9: =Table001__Page_15[[#This Row],[FİYAT]]*Table001__Page_15[[#This Row],[Sütun2]] -> 396 | J9: 400 | K9: antep | L9: =Table001__Page_15[[#This Row],[SATIŞ FİYATI]]-Table001__Page_15[[#This Row],[YUVARLAMA]] -> -4 | M9: 400 | N9: =M9-Table001__Page_15[[#This Row],[YUVARLAMA]] -> 0
A10: BAHARAT | B10: KİLO | C10: TOZ BİBER - ACI | D10: 25 | E10: KG | F10: 160 | G10: 4000 | H10: 2.5 | I10: =Table001__Page_15[[#This Row],[FİYAT]]*Table001__Page_15[[#This Row],[Sütun2]] -> 400 | J10: 400 | K10: antep | L10: =Table001__Page_15[[#This Row],[SATIŞ FİYATI]]-Table001__Page_15[[#This Row],[YUVARLAMA]] -> 0 | M10: 400 | N10: =M10-Table001__Page_15[[#This Row],[YUVARLAMA]] -> 0
A11: BAHARAT | B11: KİLO | C11: EVLİK BİBER | D11: 25 | E11: KG | F11: 180 | G11: 4500 | H11: 2.2 | I11: =Table001__Page_15[[#This Row],[FİYAT]]*Table001__Page_15[[#This Row],[Sütun2]] -> 396 | J11: 400 | K11: antep | L11: =Table001__Page_15[[#This Row],[SATIŞ FİYATI]]-Table001__Page_15[[#This Row],[YUVARLAMA]] -> -4 | M11: 400 | N11: =M11-Table001__Page_15[[#This Row],[YUVARLAMA]] -> 0
A12: BAHARAT | B12: PAKET | C12: HİNDİSTAN CEVİZİ ( İRİ ) | D12: 25 | E12: KG | F12: 150 | G12: 3750 | H12: 4 | I12: =Table001__Page_15[[#This Row],[FİYAT]]*Table001__Page_15[[#This Row],[Sütun2]] -> 600 | J12: 60 | K12: antep | L12: =Table001__Page_15[[#This Row],[SATIŞ FİYATI]]-Table001__Page_15[[#This Row],[YUVARLAMA]] -> 540 | M12: 60 | N12: =M12-Table001__Page_15[[#This Row],[YUVARLAMA]] -> 0
A13: TUZ | B13: PAKET | C13: LİMONTUZU TOZ | D13: 25 | E13: KG | F13: 70 | G13: 1750 | H13: 2.6 | I13: =Table001__Page_15[[#This Row],[FİYAT]]*Table001__Page_15[[#This Row],[Sütun2]] -> 182 | J13: =180/4 -> 45 | K13: antep | L13: =Table001__Page_15[[#This Row],[SATIŞ FİYATI]]-Table001__Page_15[[#This Row],[YUVARLAMA]] -> 137 | M13: 45 | N13: =M13-Table001__Page_15[[#This Row],[YUVARLAMA]] -> 0
A14: TUZ | B14: PAKET | C14: LİMONTUZU PARCA | D14: 25 | E14: KG | F14: 80 | G14: 2000 | H14: 2.3 | I14: =Table001__Page_15[[#This Row],[FİYAT]]*Table001__Page_15[[#This Row],[Sütun2]] -> 184 | J14: 45 | K14: antep | L14: =Table001__Page_15[[#This Row],[SATIŞ FİYATI]]-Table001__Page_15[[#This Row],[YUVARLAMA]] -> 139 | M14: 45 | N14: =M14-Table001__Page_15[[#This Row],[YUVARLAMA]] -> 0
A15: KAHVE | B15: PAKET | C15: SÜTTOZU (KAHVE KREMASI) 100 GR | D15: 25 | E15: KG | F15: 115 | G15: 2875 | H15: 5.25 | I15: =Table001__Page_15[[#This Row],[FİYAT]]*Table001__Page_15[[#This Row],[Sütun2]] -> 603.75 | J15: 60 | K15: antep | L15: =Table001__Page_15[[#This Row],[SATIŞ FİYATI]]-Table001__Page_15[[#This Row],[YUVARLAMA]] -> 543.75 | M15: 60 | N15: =M15-Table001__Page_15[[#This Row],[YUVARLAMA]] -> 0
A16: KAHVE | B16: PAKET | C16: SÜTTOZU (KAHVE KREMASI) 200 GR | D16: 0 | E16: KG | I16: =Table001__Page_15[[#This Row],[FİYAT]]*Table001__Page_15[[#This Row],[Sütun2]] -> 0 | J16: 120 | K16: antep | L16: =Table001__Page_15[[#This Row],[SATIŞ FİYATI]]-Table001__Page_15[[#This Row],[YUVARLAMA]] -> -120 | M16: 120 | N16: =M16-Table001__Page_15[[#This Row],[YUVARLAMA]] -> 0
A17: KAHVE | B17: PAKET | C17: TÜRK KAHVESİ | D17: 5 | E17: KG | F17: 440 | G17: 2200 | H17: 1.7 | I17: =Table001__Page_15[[#This Row],[FİYAT]]*Table001__Page_15[[#This Row],[Sütun2]] -> 748 | J17: 75 | K17: antep | L17: =Table001__Page_15[[#This Row],[SATIŞ FİYATI]]-Table001__Page_15[[#This Row],[YUVARLAMA]] -> 673 | M17: 75 | N17: =M17-Table001__Page_15[[#This Row],[YUVARLAMA]] -> 0
A18: BAHARAT | B18: PAKET | C18: ZENCEFİL TANE | D18: 5 | E18: KG | F18: 190 | G18: 950 | H18: 2.1 | I18: =Table001__Page_15[[#This Row],[FİYAT]]*Table001__Page_15[[#This Row],[Sütun2]] -> 399 | J18: 400 | K18: antep | L18: =Table001__Page_15[[#This Row],[SATIŞ FİYATI]]-Table001__Page_15[[#This Row],[YUVARLAMA]] -> -1 | M18: 400 | N18: =M18-Table001__Page_15[[#This Row],[YUVARLAMA]] -> 0
A19: BAHARAT | B19: KİLO | C19: ZENCEFİL TOZ | D19: 5 | E19: KG | F19: 180 | G19: 900 | H19: 2 | I19: =Table001__Page_15[[#This Row],[FİYAT]]*Table001__Page_15[[#This Row],[Sütun2]] -> 360 | J19: 400 | K19: antep | L19: =Table001__Page_15[[#This Row],[SATIŞ FİYATI]]-Table001__Page_15[[#This Row],[YUVARLAMA]] -> -40 | M19: 400 | N19: =M19-Table001__Page_15[[#This Row],[YUVARLAMA]] -> 0
A20: BAHARAT | B20: KİLO | C20: ZERDEÇAL TOZ | D20: 10 | E20: KG | F20: 125 | G20: 1250 | H20: 2 | I20: =Table001__Page_15[[#This Row],[FİYAT]]*Table001__Page_15[[#This Row],[Sütun2]] -> 250 | J20: 300 | K20: antep | L20: =Table001__Page_15[[#This Row],[SATIŞ FİYATI]]-Table001__Page_15[[#This Row],[YUVARLAMA]] -> -50 | M20: 300 | N20: =M20-Table001__Page_15[[#This Row],[YUVARLAMA]] -> 0
A21: BAHARAT | B21: KİLO | C21: KORİ (TAVUK BAHARATI) | D21: 10 | E21: KG | F21: 70 | G21: 700 | H21: 2 | I21: =Table001__Page_15[[#This Row],[FİYAT]]*Table001__Page_15[[#This Row],[Sütun2]] -> 140 | J21: 140 | K21: antep | L21: =Table001__Page_15[[#This Row],[SATIŞ FİYATI]]-Table001__Page_15[[#This Row],[YUVARLAMA]] -> 0 | M21: 140 | N21: =M21-Table001__Page_15[[#This Row],[YUVARLAMA]] -> 0
A22: ÖZ | B22: ADET | C22: NATTE LEZZET SOSU 980 GR | D22: 12 | E22: ADET | F22: 42 | G22: 504 | H22: 2.4 | I22: =Table001__Page_15[[#This Row],[FİYAT]]*Table001__Page_15[[#This Row],[Sütun2]] -> 100.8 | J22: 100 | K22: antep | L22: =Table001__Page_15[[#This Row],[SATIŞ FİYATI]]-Table001__Page_15[[#This Row],[YUVARLAMA]] -> 0.8 | M22: 100 | N22: =M22-Table001__Page_15[[#This Row],[YUVARLAMA]] -> 0
A23: ÖZ | B23: ADET | C23: NATTE LEZZET SOSU 500 GR (NAR EKŞİSİ) | D23: 24 | E23: ADET | F23: 21 | G23: 504 | H23: 2.9 | I23: =Table001__Page_15[[#This Row],[FİYAT]]*Table001__Page_15[[#This Row],[Sütun2]] -> 60.9 | J23: 60 | K23: antep | L23: =Table001__Page_15[[#This Row],[SATIŞ FİYATI]]-Table001__Page_15[[#This Row],[YUVARLAMA]] -> 0.9 | M23: 60 | N23: =M23-Table001__Page_15[[#This Row],[YUVARLAMA]] -> 0
A24: ÖZ | B24: ADET | C24: LİMONSOSU 1 KG | D24: 12 | E24: ADET | F24: 40 | G24: 480 | H24: 2 | I24: =Table001__Page_15[[#This Row],[FİYAT]]*Table001__Page_15[[#This Row],[Sütun2]] -> 80 | J24: 80 | K24: antep | L24: =Table001__Page_15[[#This Row],[SATIŞ FİYATI]]-Table001__Page_15[[#This Row],[YUVARLAMA]] -> 0 | M24: 80 | N24: =M24-Table001__Page_15[[#This Row],[YUVARLAMA]] -> 0
A25: KAHVE | B25: ADET | C25: KAFFKA MENENGİÇ KAHVESİ 150 GR | D25: 24 | E25: ADET | F25: 35 | G25: 840 | H25: 1.9 | I25: =Table001__Page_15[[#This Row],[FİYAT]]*Table001__Page_15[[#This Row],[Sütun2]] -> 66.5 | J25: 75 | K25: antep | L25: =Table001__Page_15[[#This Row],[SATIŞ FİYATI]]-Table001__Page_15[[#This Row],[YUVARLAMA]] -> -8.5 | M25: 75 | N25: =M25-Table001__Page_15[[#This Row],[YUVARLAMA]] -> 0
A26: KAHVE | B26: ADET | C26: KAFFKA OSMANLI KAHVESİ 150 GR | D26: 24 | E26: ADET | F26: 35 | G26: 840 | H26: 1.9 | I26: =Table001__Page_15[[#This Row],[FİYAT]]*Table001__Page_15[[#This Row],[Sütun2]] -> 66.5 | J26: 75 | K26: antep | L26: =Table001__Page_15[[#This Row],[SATIŞ FİYATI]]-Table001__Page_15[[#This Row],[YUVARLAMA]] -> -8.5 | M26: 75 | N26: =M26-Table001__Page_15[[#This Row],[YUVARLAMA]] -> 0
A27: KAHVE | B27: ADET | C27: KAFFKA DİBEK KAHVESİ 150 GR | D27: 24 | E27: ADET | F27: 35 | G27: 840 | H27: 1.9 | I27: =Table001__Page_15[[#This Row],[FİYAT]]*Table001__Page_15[[#This Row],[Sütun2]] -> 66.5 | J27: 75 | K27: antep | L27: =Table001__Page_15[[#This Row],[SATIŞ FİYATI]]-Table001__Page_15[[#This Row],[YUVARLAMA]] -> -8.5 | M27: 75 | N27: =M27-Table001__Page_15[[#This Row],[YUVARLAMA]] -> 0
A28: BAHARAT | B28: PAKET | C28: HASPİR | D28: 2 | E28: KG | F28: 550 | G28: 1100 | H28: 3.64 | I28: =Table001__Page_15[[#This Row],[FİYAT]]*Table001__Page_15[[#This Row],[Sütun2]] -> 2002 | J28: 2000 | K28: antep | L28: =Table001__Page_15[[#This Row],[SATIŞ FİYATI]]-Table001__Page_15[[#This Row],[YUVARLAMA]] -> 2 | M28: 2000 | N28: =M28-Table001__Page_15[[#This Row],[YUVARLAMA]] -> 0
... A47: KURUTMALIK | B47: BAĞ | C47: DOLMALIK KURU TATLI KIRMIZI BİBER | D47: 40 | E47: ADET | F47: 110 | G47: 4400 | H47: 2.1 | I47: =Table001__Page_15[[#This Row],[FİYAT]]*Table001__Page_15[[#This Row],[Sütun2]] -> 231 | J47: 250 | K47: antep | L47: =Table001__Page_15[[#This Row],[SATIŞ FİYATI]]-Table001__Page_15[[#This Row],[YUVARLAMA]] -> -19 | M47: 250 | N47: =M47-Table001__Page_15[[#This Row],[YUVARLAMA]] -> 0
A48: BAHARAT | C48: SUMAK TANE EKŞİLİ | D48: 5 | E48: KG | F48: 270 | G48: 4400 | H48: 2 | I48: =Table001__Page_15[[#This Row],[FİYAT]]*Table001__Page_15[[#This Row],[Sütun2]] -> 540 | J48: 540 | K48: antep | L48: =Table001__Page_15[[#This Row],[SATIŞ FİYATI]]-Table001__Page_15[[#This Row],[YUVARLAMA]] -> 0 | M48: 540 | N48: =M48-Table001__Page_15[[#This Row],[YUVARLAMA]] -> 0
A49: BAHARAT | C49: KIRMIZI PUL BİBER TATLI | D49: 10 | E49: KG | F49: 180 | G49: 4400 | H49: 2 | I49: =Table001__Page_15[[#This Row],[FİYAT]]*Table001__Page_15[[#This Row],[Sütun2]] -> 360 | J49: 400 | K49: antep | L49: =Table001__Page_15[[#This Row],[SATIŞ FİYATI]]-Table001__Page_15[[#This Row],[YUVARLAMA]] -> -40 | M49: 360 | N49: =M49-Table001__Page_15[[#This Row],[YUVARLAMA]] -> -40
A50: KAHVE | C50: SÜTTOZU (KAHVE KREMASI) | I50: =Table001__Page_15[[#This Row],[FİYAT]]*Table001__Page_15[[#This Row],[Sütun2]] -> 0 | L50: =Table001__Page_15[[#This Row],[SATIŞ FİYATI]]-Table001__Page_15[[#This Row],[YUVARLAMA]] -> 0 | N50: =M50-Table001__Page_15[[#This Row],[YUVARLAMA]] -> 0
A51: BAHARAT | C51: SUMAK ÖZEL | D51: 25 | E51: KG | F51: 260 | G51: 4400 | H51: 2 | I51: =Table001__Page_15[[#This Row],[FİYAT]]*Table001__Page_15[[#This Row],[Sütun2]] -> 520 | J51: 520 | K51: antep | L51: =Table001__Page_15[[#This Row],[SATIŞ FİYATI]]-Table001__Page_15[[#This Row],[YUVARLAMA]] -> 0 | M51: 520 | N51: =M51-Table001__Page_15[[#This Row],[YUVARLAMA]] -> 0
A52: BAHARAT | C52: ATOM PUL BİBER ÇOK ACI | D52: 10 | E52: KG | F52: 275 | G52: =Table001__Page_15[[#This Row],[MİKTAR]]*Table001__Page_15[[#This Row],[FİYAT]] -> 2750 | H52: 2 | I52: =Table001__Page_15[[#This Row],[FİYAT]]*Table001__Page_15[[#This Row],[Sütun2]] -> 550 | J52: 550 | K52: antep | L52: =Table001__Page_15[[#This Row],[SATIŞ FİYATI]]-Table001__Page_15[[#This Row],[YUVARLAMA]] -> 0 | M52: 550 | N52: =M52-Table001__Page_15[[#This Row],[YUVARLAMA]] -> 0
C53: PASTA SÜSÜ | F53: 85 | G53: =Table001__Page_15[[#This Row],[MİKTAR]]*Table001__Page_15[[#This Row],[FİYAT]] -> 0 | H53: 6 | I53: =Table001__Page_15[[#This Row],[FİYAT]]*Table001__Page_15[[#This Row],[Sütun2]] -> 510 | J53: 500 | K53: antep | L53: =Table001__Page_15[[#This Row],[SATIŞ FİYATI]]-Table001__Page_15[[#This Row],[YUVARLAMA]] -> 10 | M53: 500 | N53: =M53-Table001__Page_15[[#This Row],[YUVARLAMA]] -> 0
C54: KENDİR TOHUMU (ÇETENE ÇEDENE KENEVİR TOHMU) | F54: 175 | G54: =Table001__Page_15[[#This Row],[MİKTAR]]*Table001__Page_15[[#This Row],[FİYAT]] -> 0 | H54: 4 | I54: =Table001__Page_15[[#This Row],[FİYAT]]*Table001__Page_15[[#This Row],[Sütun2]] -> 700 | J54: 700 | K54: antep | L54: =Table001__Page_15[[#This Row],[SATIŞ FİYATI]]-Table001__Page_15[[#This Row],[YUVARLAMA]] -> 0 | M54: 700 | N54: =M54-Table001__Page_15[[#This Row],[YUVARLAMA]] -> 0
C55: MUSKAT TANE (HİNT CEVİZİ) | F55: 400 | G55: =Table001__Page_15[[#This Row],[MİKTAR]]*Table001__Page_15[[#This Row],[FİYAT]] -> 0 | H55: 3 | I55: =Table001__Page_15[[#This Row],[FİYAT]]*Table001__Page_15[[#This Row],[Sütun2]] -> 1200 | J55: 1200 | K55: antep | L55: =Table001__Page_15[[#This Row],[SATIŞ FİYATI]]-Table001__Page_15[[#This Row],[YUVARLAMA]] -> 0 | M55: 1200 | N55: =M55-Table001__Page_15[[#This Row],[YUVARLAMA]] -> 0
C56: KİŞNİŞ TANE | F56: 80 | G56: =Table001__Page_15[[#This Row],[MİKTAR]]*Table001__Page_15[[#This Row],[FİYAT]] -> 0 | H56: 6.2 | I56: =Table001__Page_15[[#This Row],[FİYAT]]*Table001__Page_15[[#This Row],[Sütun2]] -> 496 | J56: 500 | K56: antep | L56: =Table001__Page_15[[#This Row],[SATIŞ FİYATI]]-Table001__Page_15[[#This Row],[YUVARLAMA]] -> -4 | M56: 500 | N56: =M56-Table001__Page_15[[#This Row],[YUVARLAMA]] -> 0
C57: SIKMA ANTEP TARHANA | F57: 140 | G57: =Table001__Page_15[[#This Row],[MİKTAR]]*Table001__Page_15[[#This Row],[FİYAT]] -> 0 | H57: 2 | I57: =Table001__Page_15[[#This Row],[FİYAT]]*Table001__Page_15[[#This Row],[Sütun2]] -> 280 | J57: 280 | K57: antep | L57: =Table001__Page_15[[#This Row],[SATIŞ FİYATI]]-Table001__Page_15[[#This Row],[YUVARLAMA]] -> 0 | M57: 280 | N57: =M57-Table001__Page_15[[#This Row],[YUVARLAMA]] -> 0
C58: POLAT ŞEKERİ (NÖBET ŞEKERİ) | F58: 140 | G58: =Table001__Page_15[[#This Row],[MİKTAR]]*Table001__Page_15[[#This Row],[FİYAT]] -> 0 | H58: 1.8 | I58: =Table001__Page_15[[#This Row],[FİYAT]]*Table001__Page_15[[#This Row],[Sütun2]] -> 252 | J58: 250 | K58: antep | L58: =Table001__Page_15[[#This Row],[SATIŞ FİYATI]]-Table001__Page_15[[#This Row],[YUVARLAMA]] -> 2 | M58: 250 | N58: =M58-Table001__Page_15[[#This Row],[YUVARLAMA]] -> 0
...

Sheet STOK HAREKET
B2: CEVİZ KELEBEK (ŞİLİ) | H2: TOPLAM ÇIKIŞ | I2: {=SUM(SUMIFS(KASA!I:I, KASA!C:C, B2, KASA!B:B, {"MAL SATIŞI","MAL İADE","ÜRETİM ÇIKIŞ"}))} -> 10.072667
B4: TARİH | C4: TÜRÜ | D4: ÜRÜN | E4: HİZMET | F4: CARİ | G4: FT NO | H4: AÇIKLAMA | I4: N/K | J4: BİRİM ADET/KG | K4: BİRİM FİYAT/TL | L4: CARİ BORÇ | M4: CARİ ALACAK | N4: GELİR ADET/KG | O4: GİDER ADET/KG | P4: GELİR BİRİM FİYATI | Q4: GİDER BİRİM FİYATI | R4: KASA GİRİŞ | S4: KASA ÇIKIŞ | T4: KALAN STOK | U4: KALAN STOK DEĞERİ | V4: TOPLAM MAL ALIMI
B5: {=_xlfn._xlws.FILTER(KASA!A:R,KASA!C:C=B2)} -> 45950 | C5: MAL ALIMI | D5: CEVİZ KELEBEK (ŞİLİ) | E5: 0 | F5: TÜDAB A.Ş. | G5: FT00000000002 | H5: TÜDAB A.Ş. | I5: CARİ | J5: 5 | K5: 570 | L5: 0 | M5: 2850 | N5: 0 | O5: 5 | P5: 0 | Q5: 570 | R5: 0 | S5: 0 | T5: =IF(OR(C5="MAL ALIMI", C5="ÜRETİM GİRİŞ"), IF(J5 - MAX(0, $I$2 - (SUMIF($C$4:C4, "MAL ALIMI", $J$4:J4) + SUMIF($C$4:C4, "ÜRETİM GİRİŞ", $J$4:J4))) > 0, J5 - MAX(0, $I$2 - (SUMIF($C$4:C4, "MAL ALIMI", $J$4:J4) + SUMIF($C$4:C4, "ÜRETİM GİRİŞ", $J$4:J4))), 0), 0) -> 0 | U5: =T5*K5 -> 0 | V5: =IF(OR(C5="MAL ALIMI", C5="ÜRETİM GİRİŞ"), J5 * K5, 0) -> 2850 | W5: =V5-U5 -> 2850 | X5: TOPLAM MAL ALIŞ (BRİM/KG) | Y5: =(SUMIFS(KASA!I:I,KASA!C:C,B2,KASA!B:B,"MAL ALIMI") + SUMIFS(KASA!I:I,KASA!C:C,B2,KASA!B:B,"ÜRETİM GİRİŞ")) -> 12
B6: 45954 | C6: MAL İADE | D6: CEVİZ KELEBEK (ŞİLİ) | E6: 0 | F6: TÜDAB A.Ş. | G6: IA00000000001 | H6: TÜDAB A.Ş. | I6: CARİ | J6: 5 | K6: 570 | L6: 2850 | M6: 0 | N6: 5 | O6: 0 | P6: 570 | Q6: 0 | R6: 0 | S6: 0 | T6: =IF(OR(C6="MAL ALIMI", C6="ÜRETİM GİRİŞ"), IF(J6 - MAX(0, $I$2 - (SUMIF($C$4:C5, "MAL ALIMI", $J$4:J5) + SUMIF($C$4:C5, "ÜRETİM GİRİŞ", $J$4:J5))) > 0, J6 - MAX(0, $I$2 - (SUMIF($C$4:C5, "MAL ALIMI", $J$4:J5) + SUMIF($C$4:C5, "ÜRETİM GİRİŞ", $J$4:J5))), 0), 0) -> 0 | U6: =T6*K6 -> 0 | V6: =IF(OR(C6="MAL ALIMI", C6="ÜRETİM GİRİŞ"), J6 * K6, 0) -> 0 | W6: =V6-U6 -> 0 | X6: TOPLAM MAL ALIŞ (BRİM/TL) | Y6: =SUM(V:V) -> 6763.285
B7: 46076 | C7: MAL ALIMI | D7: CEVİZ KELEBEK (ŞİLİ) | E7: 0 | F7: TÜDAB A.Ş. | G7: 998909 | H7: TÜDAB A.Ş. | I7: CARİ | J7: 5 | K7: 585 | L7: 0 | M7: 2925 | N7: 0 | O7: 0 | P7: 0 | Q7: 0 | R7: 0 | S7: 0 | T7: =IF(OR(C7="MAL ALIMI", C7="ÜRETİM GİRİŞ"), IF(J7 - MAX(0, $I$2 - (SUMIF($C$4:C6, "MAL ALIMI", $J$4:J6) + SUMIF($C$4:C6, "ÜRETİM GİRİŞ", $J$4:J6))) > 0, J7 - MAX(0, $I$2 - (SUMIF($C$4:C6, "MAL ALIMI", $J$4:J6) + SUMIF($C$4:C6, "ÜRETİM GİRİŞ", $J$4:J6))), 0), 0) -> 0 | U7: =T7*K7 -> 0 | V7: =IF(OR(C7="MAL ALIMI", C7="ÜRETİM GİRİŞ"), J7 * K7, 0) -> 2925 | W7: =V7-U7 -> 2925 | X7: ORTALAMA ALIŞ FİYATI | Y7: =Y6/Y5 -> 563.60708
B8: 46081 | C8: MAL SATIŞI | D8: CEVİZ KELEBEK (ŞİLİ) | E8: 0 | F8: TFK-POS | G8: ST00000001426 | H8: SATIŞ | I8: POS | J8: 1 | K8: 750 | L8: 750 | M8: 0 | N8: 0 | O8: 0 | P8: 0 | Q8: 0 | R8: 0 | S8: 0 | T8: =IF(OR(C8="MAL ALIMI", C8="ÜRETİM GİRİŞ"), IF(J8 - MAX(0, $I$2 - (SUMIF($C$4:C7, "MAL ALIMI", $J$4:J7) + SUMIF($C$4:C7, "ÜRETİM GİRİŞ", $J$4:J7))) > 0, J8 - MAX(0, $I$2 - (SUMIF($C$4:C7, "MAL ALIMI", $J$4:J7) + SUMIF($C$4:C7, "ÜRETİM GİRİŞ", $J$4:J7))), 0), 0) -> 0 | U8: =T8*K8 -> 0 | V8: =IF(OR(C8="MAL ALIMI", C8="ÜRETİM GİRİŞ"), J8 * K8, 0) -> 0 | W8: =V8-U8 -> 0 | X8: TOPLAM SATIŞ ÇIKIŞI BİRİM | Y8: {=SUM(SUMIFS(KASA!I:I, KASA!C:C, B2, KASA!B:B, {"MAL SATIŞI"}))} -> 5.0726667
B9: 46085 | C9: MAL SATIŞI | D9: CEVİZ KELEBEK (ŞİLİ) | E9: 0 | F9: 0 | G9: ST00000001479 | H9: SATIŞ | I9: NAKİT | J9: 0.5 | K9: 750 | L9: 0 | M9: 0 | N9: 0 | O9: 0 | P9: 0 | Q9: 0 | R9: 375 | S9: 0 | T9: =IF(OR(C9="MAL ALIMI", C9="ÜRETİM GİRİŞ"), IF(J9 - MAX(0, $I$2 - (SUMIF($C$4:C8, "MAL ALIMI", $J$4:J8) + SUMIF($C$4:C8, "ÜRETİM GİRİŞ", $J$4:J8))) > 0, J9 - MAX(0, $I$2 - (SUMIF($C$4:C8, "MAL ALIMI", $J$4:J8) + SUMIF($C$4:C8, "ÜRETİM GİRİŞ", $J$4:J8))), 0), 0) -> 0 | U9: =T9*K9 -> 0 | V9: =IF(OR(C9="MAL ALIMI", C9="ÜRETİM GİRİŞ"), J9 * K9, 0) -> 0 | W9: =V9-U9 -> 0 | X9: TOPLAM SATIŞ TL | Y9: =(SUMIFS(KASA!K:K, KASA!C:C, B2, KASA!B:B, "MAL SATIŞI") + SUMIFS(KASA!Q:Q, KASA!C:C, B2, KASA!B:B, "MAL SATIŞI")) -> 3804.5
B10: 46086 | C10: MAL SATIŞI | D10: CEVİZ KELEBEK (ŞİLİ) | E10: 0 | F10: TFK-POS | G10: ST00000001497 | H10: SATIŞ | I10: POS | J10: 0.156 | K10: 750 | L10: 117 | M10: 0 | N10: 0 | O10: 0 | P10: 0 | Q10: 0 | R10: 0 | S10: 0 | T10: =IF(OR(C10="MAL ALIMI", C10="ÜRETİM GİRİŞ"), IF(J10 - MAX(0, $I$2 - (SUMIF($C$4:C9, "MAL ALIMI", $J$4:J9) + SUMIF($C$4:C9, "ÜRETİM GİRİŞ", $J$4:J9))) > 0, J10 - MAX(0, $I$2 - (SUMIF($C$4:C9, "MAL ALIMI", $J$4:J9) + SUMIF($C$4:C9, "ÜRETİM GİRİŞ", $J$4:J9))), 0), 0) -> 0 | U10: =T10*K10 -> 0 | V10: =IF(OR(C10="MAL ALIMI", C10="ÜRETİM GİRİŞ"), J10 * K10, 0) -> 0 | W10: =V10-U10 -> 0 | X10: ORTALAMA SATIŞ FİYATI | Y10: =Y9/Y8 -> 750
B11: 46095 | C11: MAL SATIŞI | D11: CEVİZ KELEBEK (ŞİLİ) | E11: 0 | F11: 0 | G11: ST00000001617 | H11: SATIŞ | I11: NAKİT | J11: 0.504 | K11: 750 | L11: 0 | M11: 0 | N11: 0 | O11: 0 | P11: 0 | Q11: 0 | R11: 378 | S11: 0 | T11: =IF(OR(C11="MAL ALIMI", C11="ÜRETİM GİRİŞ"), IF(J11 - MAX(0, $I$2 - (SUMIF($C$4:C10, "MAL ALIMI", $J$4:J10) + SUMIF($C$4:C10, "ÜRETİM GİRİŞ", $J$4:J10))) > 0, J11 - MAX(0, $I$2 - (SUMIF($C$4:C10, "MAL ALIMI", $J$4:J10) + SUMIF($C$4:C10, "ÜRETİM GİRİŞ", $J$4:J10))), 0), 0) -> 0 | U11: =T11*K11 -> 0 | V11: =IF(OR(C11="MAL ALIMI", C11="ÜRETİM GİRİŞ"), J11 * K11, 0) -> 0 | W11: =V11-U11 -> 0 | X11: TOPLAM İADE ÇIKIŞI BİRİM | Y11: {=SUM(SUMIFS(KASA!I:I, KASA!C:C, B2, KASA!B:B, {"MAL İADE"}))} -> 5
B12: 46113 | C12: MAL SATIŞI | D12: CEVİZ KELEBEK (ŞİLİ) | E12: 0 | F12: TFK-POS | G12: ST00000001787 | H12: SATIŞ | I12: POS | J12: 0.184 | K12: 750 | L12: 138 | M12: 0 | N12: 0 | O12: 0 | P12: 0 | Q12: 0 | R12: 0 | S12: 0 | T12: =IF(OR(C12="MAL ALIMI", C12="ÜRETİM GİRİŞ"), IF(J12 - MAX(0, $I$2 - (SUMIF($C$4:C11, "MAL ALIMI", $J$4:J11) + SUMIF($C$4:C11, "ÜRETİM GİRİŞ", $J$4:J11))) > 0, J12 - MAX(0, $I$2 - (SUMIF($C$4:C11, "MAL ALIMI", $J$4:J11) + SUMIF($C$4:C11, "ÜRETİM GİRİŞ", $J$4:J11))), 0), 0) -> 0 | U12: =T12*K12 -> 0 | V12: =IF(OR(C12="MAL ALIMI", C12="ÜRETİM GİRİŞ"), J12 * K12, 0) -> 0 | W12: =V12-U12 -> 0 | X12: TOPLAM İADE ÇIKIŞI TL | Y12: =(SUMIFS(KASA!K:K, KASA!C:C, B2, KASA!B:B, "MAL İADE") + SUMIFS(KASA!Q:Q, KASA!C:C, B2, KASA!B:B, "MAL İADE")) -> 2850
B13: 46115 | C13: MAL SATIŞI | D13: CEVİZ KELEBEK (ŞİLİ) | E13: 0 | F13: TFK-POS | G13: ST00000001818 | H13: SATIŞ | I13: POS | J13: 1 | K13: 750 | L13: 750 | M13: 0 | N13: 0 | O13: 0 | P13: 0 | Q13: 0 | R13: 0 | S13: 0 | T13: =IF(OR(C13="MAL ALIMI", C13="ÜRETİM GİRİŞ"), IF(J13 - MAX(0, $I$2 - (SUMIF($C$4:C12, "MAL ALIMI", $J$4:J12) + SUMIF($C$4:C12, "ÜRETİM GİRİŞ", $J$4:J12))) > 0, J13 - MAX(0, $I$2 - (SUMIF($C$4:C12, "MAL ALIMI", $J$4:J12) + SUMIF($C$4:C12, "ÜRETİM GİRİŞ", $J$4:J12))), 0), 0) -> 0 | U13: =T13*K13 -> 0 | V13: =IF(OR(C13="MAL ALIMI", C13="ÜRETİM GİRİŞ"), J13 * K13, 0) -> 0 | W13: =V13-U13 -> 0 | X13: TOPLAM ÜRETİM ÇIKIŞI BİRİM | Y13: {=SUM(SUMIFS(KASA!I:I, KASA!C:C, B2, KASA!B:B, {"ÜRETİM ÇIKIŞ"}))} -> 0
B14: 46116 | C14: MAL SATIŞI | D14: CEVİZ KELEBEK (ŞİLİ) | E14: 0 | F14: 0 | G14: ST00000001827 | H14: SATIŞ - SUAT | I14: NAKİT | J14: 0.246 | K14: 750 | L14: 0 | M14: 0 | N14: 0 | O14: 0 | P14: 0 | Q14: 0 | R14: 184.5 | S14: 0 | T14: =IF(OR(C14="MAL ALIMI", C14="ÜRETİM GİRİŞ"), IF(J14 - MAX(0, $I$2 - (SUMIF($C$4:C13, "MAL ALIMI", $J$4:J13) + SUMIF($C$4:C13, "ÜRETİM GİRİŞ", $J$4:J13))) > 0, J14 - MAX(0, $I$2 - (SUMIF($C$4:C13, "MAL ALIMI", $J$4:J13) + SUMIF($C$4:C13, "ÜRETİM GİRİŞ", $J$4:J13))), 0), 0) -> 0 | U14: =T14*K14 -> 0 | V14: =IF(OR(C14="MAL ALIMI", C14="ÜRETİM GİRİŞ"), J14 * K14, 0) -> 0 | W14: =V14-U14 -> 0 | X14: TOPLAM ÜRETİM ÇIKIŞI TL | Y14: =(SUMIFS(KASA!K:K, KASA!C:C, B2, KASA!B:B, "ÜRETİM ÇIKIŞ") + SUMIFS(KASA!Q:Q, KASA!C:C, B2, KASA!B:B, "ÜRETİM ÇIKIŞ")) -> 0
B15: 46124 | C15: MAL SATIŞI | D15: CEVİZ KELEBEK (ŞİLİ) | E15: 0 | F15: TFK-POS | G15: ST00000001917 | H15: SATIŞ | I15: POS | J15: 0.5 | K15: 750 | L15: 375 | M15: 0 | N15: 0 | O15: 0 | P15: 0 | Q15: 0 | R15: 0 | S15: 0 | T15: =IF(OR(C15="MAL ALIMI", C15="ÜRETİM GİRİŞ"), IF(J15 - MAX(0, $I$2 - (SUMIF($C$4:C14, "MAL ALIMI", $J$4:J14) + SUMIF($C$4:C14, "ÜRETİM GİRİŞ", $J$4:J14))) > 0, J15 - MAX(0, $I$2 - (SUMIF($C$4:C14, "MAL ALIMI", $J$4:J14) + SUMIF($C$4:C14, "ÜRETİM GİRİŞ", $J$4:J14))), 0), 0) -> 0 | U15: =T15*K15 -> 0 | V15: =IF(OR(C15="MAL ALIMI", C15="ÜRETİM GİRİŞ"), J15 * K15, 0) -> 0 | W15: =V15-U15 -> 0 | X15: KALAN STOK BİRİM | Y15: =SUM(T:T) -> 1.9273333
B16: 46147 | C16: MAL SATIŞI | D16: CEVİZ KELEBEK (ŞİLİ) | E16: 0 | F16: 0 | G16: ST00000002180 | H16: SATIŞ | I16: NAKİT | J16: 0.13333333 | K16: 750 | L16: 0 | M16: 0 | N16: 0 | O16: 0 | P16: 0 | Q16: 0 | R16: 100 | S16: 0 | T16: =IF(OR(C16="MAL ALIMI", C16="ÜRETİM GİRİŞ"), IF(J16 - MAX(0, $I$2 - (SUMIF($C$4:C15, "MAL ALIMI", $J$4:J15) + SUMIF($C$4:C15, "ÜRETİM GİRİŞ", $J$4:J15))) > 0, J16 - MAX(0, $I$2 - (SUMIF($C$4:C15, "MAL ALIMI", $J$4:J15) + SUMIF($C$4:C15, "ÜRETİM GİRİŞ", $J$4:J15))), 0), 0) -> 0 | U16: =T16*K16 -> 0 | V16: =IF(OR(C16="MAL ALIMI", C16="ÜRETİM GİRİŞ"), J16 * K16, 0) -> 0 | W16: =V16-U16 -> 0 | X16: KALAN STOK TL | Y16: =SUM(U:U) -> 952.37731
B17: 46160 | C17: MAL SATIŞI | D17: CEVİZ KELEBEK (ŞİLİ) | E17: 0 | F17: TFK-POS | G17: ST00000002294 | H17: SATIŞ | I17: POS | J17: 0.5 | K17: 750 | L17: 375 | M17: 0 | N17: 0 | O17: 0 | P17: 0 | Q17: 0 | R17: 0 | S17: 0 | T17: =IF(OR(C17="MAL ALIMI", C17="ÜRETİM GİRİŞ"), IF(J17 - MAX(0, $I$2 - (SUMIF($C$4:C16, "MAL ALIMI", $J$4:J16) + SUMIF($C$4:C16, "ÜRETİM GİRİŞ", $J$4:J16))) > 0, J17 - MAX(0, $I$2 - (SUMIF($C$4:C16, "MAL ALIMI", $J$4:J16) + SUMIF($C$4:C16, "ÜRETİM GİRİŞ", $J$4:J16))), 0), 0) -> 0 | U17: =T17*K17 -> 0 | V17: =IF(OR(C17="MAL ALIMI", C17="ÜRETİM GİRİŞ"), J17 * K17, 0) -> 0 | W17: =V17-U17 -> 0
B18: 46167 | C18: MAL SATIŞI | D18: CEVİZ KELEBEK (ŞİLİ) | E18: 0 | F18: TFK-POS | G18: ST00000002356 | H18: SATIŞ | I18: POS | J18: 0.2 | K18: 750 | L18: 150 | M18: 0 | N18: 0 | O18: 0 | P18: 0 | Q18: 0 | R18: 0 | S18: 0 | T18: =IF(OR(C18="MAL ALIMI", C18="ÜRETİM GİRİŞ"), IF(J18 - MAX(0, $I$2 - (SUMIF($C$4:C17, "MAL ALIMI", $J$4:J17) + SUMIF($C$4:C17, "ÜRETİM GİRİŞ", $J$4:J17))) > 0, J18 - MAX(0, $I$2 - (SUMIF($C$4:C17, "MAL ALIMI", $J$4:J17) + SUMIF($C$4:C17, "ÜRETİM GİRİŞ", $J$4:J17))), 0), 0) -> 0 | U18: =T18*K18 -> 0 | V18: =IF(OR(C18="MAL ALIMI", C18="ÜRETİM GİRİŞ"), J18 * K18, 0) -> 0 | W18: =V18-U18 -> 0
B19: 46191 | C19: MAL SATIŞI | D19: CEVİZ KELEBEK (ŞİLİ) | E19: 0 | F19: TFK-POS | G19: ST00000002519 | H19: SATIŞ | I19: POS | J19: 0.14933333 | K19: 750 | L19: 112 | M19: 0 | N19: 0 | O19: 0 | P19: 0 | Q19: 0 | R19: 0 | S19: 0 | T19: =IF(OR(C19="MAL ALIMI", C19="ÜRETİM GİRİŞ"), IF(J19 - MAX(0, $I$2 - (SUMIF($C$4:C18, "MAL ALIMI", $J$4:J18) + SUMIF($C$4:C18, "ÜRETİM GİRİŞ", $J$4:J18))) > 0, J19 - MAX(0, $I$2 - (SUMIF($C$4:C18, "MAL ALIMI", $J$4:J18) + SUMIF($C$4:C18, "ÜRETİM GİRİŞ", $J$4:J18))), 0), 0) -> 0 | U19: =T19*K19 -> 0 | V19: =IF(OR(C19="MAL ALIMI", C19="ÜRETİM GİRİŞ"), J19 * K19, 0) -> 0 | W19: =V19-U19 -> 0
B20: 46219 | C20: MAL ALIMI | D20: CEVİZ KELEBEK (ŞİLİ) | E20: 0 | F20: NEVANTAT KURUYEMİŞ | G20: NTA20260000000259 | H20: NEVANTAT MAL ALIMI | I20: CARİ | J20: 2 | K20: 494.1425 | L20: 0 | M20: 988.285 | N20: 0 | O20: 0 | P20: 0 | Q20: 0 | R20: 0 | S20: 0 | T20: =IF(OR(C20="MAL ALIMI", C20="ÜRETİM GİRİŞ"), IF(J20 - MAX(0, $I$2 - (SUMIF($C$4:C19, "MAL ALIMI", $J$4:J19) + SUMIF($C$4:C19, "ÜRETİM GİRİŞ", $J$4:J19))) > 0, J20 - MAX(0, $I$2 - (SUMIF($C$4:C19, "MAL ALIMI", $J$4:J19) + SUMIF($C$4:C19, "ÜRETİM GİRİŞ", $J$4:J19))), 0), 0) -> 1.9273333 | U20: =T20*K20 -> 952.37731 | V20: =IF(OR(C20="MAL ALIMI", C20="ÜRETİM GİRİŞ"), J20 * K20, 0) -> 988.285 | W20: =V20-U20 -> 35.907688
T21: =IF(OR(C21="MAL ALIMI", C21="ÜRETİM GİRİŞ"), IF(J21 - MAX(0, $I$2 - (SUMIF($C$4:C20, "MAL ALIMI", $J$4:J20) + SUMIF($C$4:C20, "ÜRETİM GİRİŞ", $J$4:J20))) > 0, J21 - MAX(0, $I$2 - (SUMIF($C$4:C20, "MAL ALIMI", $J$4:J20) + SUMIF($C$4:C20, "ÜRETİM GİRİŞ", $J$4:J20))), 0), 0) -> 0 | U21: =T21*K21 -> 0 | V21: =IF(OR(C21="MAL ALIMI", C21="ÜRETİM GİRİŞ"), J21 * K21, 0) -> 0 | W21: =V21-U21 -> 0
T22: =IF(OR(C22="MAL ALIMI", C22="ÜRETİM GİRİŞ"), IF(J22 - MAX(0, $I$2 - (SUMIF($C$4:C21, "MAL ALIMI", $J$4:J21) + SUMIF($C$4:C21, "ÜRETİM GİRİŞ", $J$4:J21))) > 0, J22 - MAX(0, $I$2 - (SUMIF($C$4:C21, "MAL ALIMI", $J$4:J21) + SUMIF($C$4:C21, "ÜRETİM GİRİŞ", $J$4:J21))), 0), 0) -> 0 | U22: =T22*K22 -> 0 | V22: =IF(OR(C22="MAL ALIMI", C22="ÜRETİM GİRİŞ"), J22 * K22, 0) -> 0 | W22: =V22-U22 -> 0
T23: =IF(OR(C23="MAL ALIMI", C23="ÜRETİM GİRİŞ"), IF(J23 - MAX(0, $I$2 - (SUMIF($C$4:C22, "MAL ALIMI", $J$4:J22) + SUMIF($C$4:C22, "ÜRETİM GİRİŞ", $J$4:J22))) > 0, J23 - MAX(0, $I$2 - (SUMIF($C$4:C22, "MAL ALIMI", $J$4:J22) + SUMIF($C$4:C22, "ÜRETİM GİRİŞ", $J$4:J22))), 0), 0) -> 0 | U23: =T23*K23 -> 0 | V23: =IF(OR(C23="MAL ALIMI", C23="ÜRETİM GİRİŞ"), J23 * K23, 0) -> 0 | W23: =V23-U23 -> 0
T24: =IF(OR(C24="MAL ALIMI", C24="ÜRETİM GİRİŞ"), IF(J24 - MAX(0, $I$2 - (SUMIF($C$4:C23, "MAL ALIMI", $J$4:J23) + SUMIF($C$4:C23, "ÜRETİM GİRİŞ", $J$4:J23))) > 0, J24 - MAX(0, $I$2 - (SUMIF($C$4:C23, "MAL ALIMI", $J$4:J23) + SUMIF($C$4:C23, "ÜRETİM GİRİŞ", $J$4:J23))), 0), 0) -> 0 | U24: =T24*K24 -> 0 | V24: =IF(OR(C24="MAL ALIMI", C24="ÜRETİM GİRİŞ"), J24 * K24, 0) -> 0 | W24: =V24-U24 -> 0
T25: =IF(OR(C25="MAL ALIMI", C25="ÜRETİM GİRİŞ"), IF(J25 - MAX(0, $I$2 - (SUMIF($C$4:C24, "MAL ALIMI", $J$4:J24) + SUMIF($C$4:C24, "ÜRETİM GİRİŞ", $J$4:J24))) > 0, J25 - MAX(0, $I$2 - (SUMIF($C$4:C24, "MAL ALIMI", $J$4:J24) + SUMIF($C$4:C24, "ÜRETİM GİRİŞ", $J$4:J24))), 0), 0) -> 0 | U25: =T25*K25 -> 0 | V25: =IF(OR(C25="MAL ALIMI", C25="ÜRETİM GİRİŞ"), J25 * K25, 0) -> 0 | W25: =V25-U25 -> 0
T26: =IF(OR(C26="MAL ALIMI", C26="ÜRETİM GİRİŞ"), IF(J26 - MAX(0, $I$2 - (SUMIF($C$4:C25, "MAL ALIMI", $J$4:J25) + SUMIF($C$4:C25, "ÜRETİM GİRİŞ", $J$4:J25))) > 0, J26 - MAX(0, $I$2 - (SUMIF($C$4:C25, "MAL ALIMI", $J$4:J25) + SUMIF($C$4:C25, "ÜRETİM GİRİŞ", $J$4:J25))), 0), 0) -> 0 | U26: =T26*K26 -> 0 | V26: =IF(OR(C26="MAL ALIMI", C26="ÜRETİM GİRİŞ"), J26 * K26, 0) -> 0 | W26: =V26-U26 -> 0
T27: =IF(OR(C27="MAL ALIMI", C27="ÜRETİM GİRİŞ"), IF(J27 - MAX(0, $I$2 - (SUMIF($C$4:C26, "MAL ALIMI", $J$4:J26) + SUMIF($C$4:C26, "ÜRETİM GİRİŞ", $J$4:J26))) > 0, J27 - MAX(0, $I$2 - (SUMIF($C$4:C26, "MAL ALIMI", $J$4:J26) + SUMIF($C$4:C26, "ÜRETİM GİRİŞ", $J$4:J26))), 0), 0) -> 0 | U27: =T27*K27 -> 0 | V27: =IF(OR(C27="MAL ALIMI", C27="ÜRETİM GİRİŞ"), J27 * K27, 0) -> 0 | W27: =V27-U27 -> 0
T28: =IF(OR(C28="MAL ALIMI", C28="ÜRETİM GİRİŞ"), IF(J28 - MAX(0, $I$2 - (SUMIF($C$4:C27, "MAL ALIMI", $J$4:J27) + SUMIF($C$4:C27, "ÜRETİM GİRİŞ", $J$4:J27))) > 0, J28 - MAX(0, $I$2 - (SUMIF($C$4:C27, "MAL ALIMI", $J$4:J27) + SUMIF($C$4:C27, "ÜRETİM GİRİŞ", $J$4:J27))), 0), 0) -> 0 | U28: =T28*K28 -> 0 | V28: =IF(OR(C28="MAL ALIMI", C28="ÜRETİM GİRİŞ"), J28 * K28, 0) -> 0 | W28: =V28-U28 -> 0
T29: =IF(OR(C29="MAL ALIMI", C29="ÜRETİM GİRİŞ"), IF(J29 - MAX(0, $I$2 - (SUMIF($C$4:C28, "MAL ALIMI", $J$4:J28) + SUMIF($C$4:C28, "ÜRETİM GİRİŞ", $J$4:J28))) > 0, J29 - MAX(0, $I$2 - (SUMIF($C$4:C28, "MAL ALIMI", $J$4:J28) + SUMIF($C$4:C28, "ÜRETİM GİRİŞ", $J$4:J28))), 0), 0) -> 0 | U29: =T29*K29 -> 0 | V29: =IF(OR(C29="MAL ALIMI", C29="ÜRETİM GİRİŞ"), J29 * K29, 0) -> 0 | W29: =V29-U29 -> 0
T30: =IF(OR(C30="MAL ALIMI", C30="ÜRETİM GİRİŞ"), IF(J30 - MAX(0, $I$2 - (SUMIF($C$4:C29, "MAL ALIMI", $J$4:J29) + SUMIF($C$4:C29, "ÜRETİM GİRİŞ", $J$4:J29))) > 0, J30 - MAX(0, $I$2 - (SUMIF($C$4:C29, "MAL ALIMI", $J$4:J29) + SUMIF($C$4:C29, "ÜRETİM GİRİŞ", $J$4:J29))), 0), 0) -> 0 | U30: =T30*K30 -> 0 | V30: =IF(OR(C30="MAL ALIMI", C30="ÜRETİM GİRİŞ"), J30 * K30, 0) -> 0 | W30: =V30-U30 -> 0
T31: =IF(OR(C31="MAL ALIMI", C31="ÜRETİM GİRİŞ"), IF(J31 - MAX(0, $I$2 - (SUMIF($C$4:C30, "MAL ALIMI", $J$4:J30) + SUMIF($C$4:C30, "ÜRETİM GİRİŞ", $J$4:J30))) > 0, J31 - MAX(0, $I$2 - (SUMIF($C$4:C30, "MAL ALIMI", $J$4:J30) + SUMIF($C$4:C30, "ÜRETİM GİRİŞ", $J$4:J30))), 0), 0) -> 0 | U31: =T31*K31 -> 0 | V31: =IF(OR(C31="MAL ALIMI", C31="ÜRETİM GİRİŞ"), J31 * K31, 0) -> 0 | W31: =V31-U31 -> 0
T32: =IF(OR(C32="MAL ALIMI", C32="ÜRETİM GİRİŞ"), IF(J32 - MAX(0, $I$2 - (SUMIF($C$4:C31, "MAL ALIMI", $J$4:J31) + SUMIF($C$4:C31, "ÜRETİM GİRİŞ", $J$4:J31))) > 0, J32 - MAX(0, $I$2 - (SUMIF($C$4:C31, "MAL ALIMI", $J$4:J31) + SUMIF($C$4:C31, "ÜRETİM GİRİŞ", $J$4:J31))), 0), 0) -> 0 | U32: =T32*K32 -> 0 | V32: =IF(OR(C32="MAL ALIMI", C32="ÜRETİM GİRİŞ"), J32 * K32, 0) -> 0 | W32: =V32-U32 -> 0
... T58: =IF(OR(C58="MAL ALIMI", C58="ÜRETİM GİRİŞ"), IF(J58 - MAX(0, $I$2 - (SUMIF($C$4:C57, "MAL ALIMI", $J$4:J57) + SUMIF($C$4:C57, "ÜRETİM GİRİŞ", $J$4:J57))) > 0, J58 - MAX(0, $I$2 - (SUMIF($C$4:C57, "MAL ALIMI", $J$4:J57) + SUMIF($C$4:C57, "ÜRETİM GİRİŞ", $J$4:J57))), 0), 0) -> 0 | U58: =T58*K58 -> 0 | V58: =IF(OR(C58="MAL ALIMI", C58="ÜRETİM GİRİŞ"), J58 * K58, 0) -> 0 | W58: =V58-U58 -> 0
T59: =IF(OR(C59="MAL ALIMI", C59="ÜRETİM GİRİŞ"), IF(J59 - MAX(0, $I$2 - (SUMIF($C$4:C58, "MAL ALIMI", $J$4:J58) + SUMIF($C$4:C58, "ÜRETİM GİRİŞ", $J$4:J58))) > 0, J59 - MAX(0, $I$2 - (SUMIF($C$4:C58, "MAL ALIMI", $J$4:J58) + SUMIF($C$4:C58, "ÜRETİM GİRİŞ", $J$4:J58))), 0), 0) -> 0 | U59: =T59*J59 -> 0 | V59: =IF(OR(C59="MAL ALIMI", C59="ÜRETİM GİRİŞ"),#REF! * J59, 0) -> 0 | W59: =V59-U59 -> 0
T60: =IF(OR(C60="MAL ALIMI", C60="ÜRETİM GİRİŞ"), IF(J60 - MAX(0, $I$2 - (SUMIF($C$4:C59, "MAL ALIMI", $J$4:J59) + SUMIF($C$4:C59, "ÜRETİM GİRİŞ", $J$4:J59))) > 0, J60 - MAX(0, $I$2 - (SUMIF($C$4:C59, "MAL ALIMI", $J$4:J59) + SUMIF($C$4:C59, "ÜRETİM GİRİŞ", $J$4:J59))), 0), 0) -> 0 | U60: =T60*K60 -> 0 | V60: =IF(OR(C60="MAL ALIMI", C60="ÜRETİM GİRİŞ"), J60 * K60, 0) -> 0 | W60: =V60-U60 -> 0
T61: =IF(OR(C61="MAL ALIMI", C61="ÜRETİM GİRİŞ"), IF(J61 - MAX(0, $I$2 - (SUMIF($C$4:C60, "MAL ALIMI", $J$4:J60) + SUMIF($C$4:C60, "ÜRETİM GİRİŞ", $J$4:J60))) > 0, J61 - MAX(0, $I$2 - (SUMIF($C$4:C60, "MAL ALIMI", $J$4:J60) + SUMIF($C$4:C60, "ÜRETİM GİRİŞ", $J$4:J60))), 0), 0) -> 0 | U61: =T61*K61 -> 0 | V61: =IF(OR(C61="MAL ALIMI", C61="ÜRETİM GİRİŞ"), J61 * K61, 0) -> 0 | W61: =V61-U61 -> 0
T62: =IF(OR(C62="MAL ALIMI", C62="ÜRETİM GİRİŞ"), IF(J62 - MAX(0, $I$2 - (SUMIF($C$4:C61, "MAL ALIMI", $J$4:J61) + SUMIF($C$4:C61, "ÜRETİM GİRİŞ", $J$4:J61))) > 0, J62 - MAX(0, $I$2 - (SUMIF($C$4:C61, "MAL ALIMI", $J$4:J61) + SUMIF($C$4:C61, "ÜRETİM GİRİŞ", $J$4:J61))), 0), 0) -> 0 | U62: =T62*K62 -> 0 | V62: =IF(OR(C62="MAL ALIMI", C62="ÜRETİM GİRİŞ"), J62 * K62, 0) -> 0 | W62: =V62-U62 -> 0
T63: =IF(OR(C63="MAL ALIMI", C63="ÜRETİM GİRİŞ"), IF(J63 - MAX(0, $I$2 - (SUMIF($C$4:C62, "MAL ALIMI", $J$4:J62) + SUMIF($C$4:C62, "ÜRETİM GİRİŞ", $J$4:J62))) > 0, J63 - MAX(0, $I$2 - (SUMIF($C$4:C62, "MAL ALIMI", $J$4:J62) + SUMIF($C$4:C62, "ÜRETİM GİRİŞ", $J$4:J62))), 0), 0) -> 0 | U63: =T63*K63 -> 0 | V63: =IF(OR(C63="MAL ALIMI", C63="ÜRETİM GİRİŞ"), J63 * K63, 0) -> 0 | W63: =V63-U63 -> 0
T64: =IF(OR(C64="MAL ALIMI", C64="ÜRETİM GİRİŞ"), IF(J64 - MAX(0, $I$2 - (SUMIF($C$4:C63, "MAL ALIMI", $J$4:J63) + SUMIF($C$4:C63, "ÜRETİM GİRİŞ", $J$4:J63))) > 0, J64 - MAX(0, $I$2 - (SUMIF($C$4:C63, "MAL ALIMI", $J$4:J63) + SUMIF($C$4:C63, "ÜRETİM GİRİŞ", $J$4:J63))), 0), 0) -> 0 | U64: =T64*K64 -> 0 | V64: =IF(OR(C64="MAL ALIMI", C64="ÜRETİM GİRİŞ"), J64 * K64, 0) -> 0 | W64: =V64-U64 -> 0
T65: =IF(OR(C65="MAL ALIMI", C65="ÜRETİM GİRİŞ"), IF(J65 - MAX(0, $I$2 - (SUMIF($C$4:C64, "MAL ALIMI", $J$4:J64) + SUMIF($C$4:C64, "ÜRETİM GİRİŞ", $J$4:J64))) > 0, J65 - MAX(0, $I$2 - (SUMIF($C$4:C64, "MAL ALIMI", $J$4:J64) + SUMIF($C$4:C64, "ÜRETİM GİRİŞ", $J$4:J64))), 0), 0) -> 0 | U65: =T65*K65 -> 0 | V65: =IF(OR(C65="MAL ALIMI", C65="ÜRETİM GİRİŞ"), J65 * K65, 0) -> 0 | W65: =V65-U65 -> 0
T66: =IF(OR(C66="MAL ALIMI", C66="ÜRETİM GİRİŞ"), IF(J66 - MAX(0, $I$2 - (SUMIF($C$4:C65, "MAL ALIMI", $J$4:J65) + SUMIF($C$4:C65, "ÜRETİM GİRİŞ", $J$4:J65))) > 0, J66 - MAX(0, $I$2 - (SUMIF($C$4:C65, "MAL ALIMI", $J$4:J65) + SUMIF($C$4:C65, "ÜRETİM GİRİŞ", $J$4:J65))), 0), 0) -> 0 | U66: =T66*K66 -> 0 | V66: =IF(OR(C66="MAL ALIMI", C66="ÜRETİM GİRİŞ"), J66 * K66, 0) -> 0 | W66: =V66-U66 -> 0
T67: =IF(OR(C67="MAL ALIMI", C67="ÜRETİM GİRİŞ"), IF(J67 - MAX(0, $I$2 - (SUMIF($C$4:C66, "MAL ALIMI", $J$4:J66) + SUMIF($C$4:C66, "ÜRETİM GİRİŞ", $J$4:J66))) > 0, J67 - MAX(0, $I$2 - (SUMIF($C$4:C66, "MAL ALIMI", $J$4:J66) + SUMIF($C$4:C66, "ÜRETİM GİRİŞ", $J$4:J66))), 0), 0) -> 0 | U67: =T67*K67 -> 0 | V67: =IF(OR(C67="MAL ALIMI", C67="ÜRETİM GİRİŞ"), J67 * K67, 0) -> 0 | W67: =V67-U67 -> 0
...

Sheet STOK RAPORU
C1: ÜRÜN | D1: ALIM BİRİM | E1: ALIM FİYAT | F1: SATIŞ BİRİM | G1: ALIŞ İADE BİRİM | H1: alış iade toplam | I1: TOPLAM ÇIKIŞ BİRİM | J1: MALİYET | K1: NAKİT SATIŞ | L1: POS SATIŞ | M1: TOPLAM SATIŞ | N1: KAR TL | O1: ORAN | P1: ORTALAMA SATIŞ FİYATI | Q1: KALAN STOK | R1: KALAN STOK DEĞERİ | S1: TÜM MAL ALIŞLAR | T1: STOK SAYIM | U1: EKSİK / FAZLA | V1: (iade öncesi) kalan stok birim | W1: (iade öncesi) kalan stok tl | X1: (iade sonrası) kalan stok birim | Y1: (iade sonrası) kalan stok tl | Z1: toplam mal alımı | AA1: satılan malın maliyeti
C2: KARABİBER ÇEKİLMİŞ | D2: =SUMIFS(KASA!$I:$I, KASA!$C:$C, $C2, KASA!$B:$B, "MAL ALIMI") + SUMIFS(KASA!$I:$I, KASA!$C:$C, $C2, KASA!$B:$B, "ÜRETİM GİRİŞ") -> 50 | E2: =Z2/D2 -> 330 | F2: =SUMIFS(KASA!$I:$I, KASA!$C:$C, $C2, KASA!$B:$B, "MAL SATIŞI") + SUMIFS(KASA!$I:$I, KASA!$C:$C, $C2, KASA!$B:$B, "ÜRETİM ÇIKIŞ") -> 26.466581 | G2: =SUMIFS(KASA!$I:$I, KASA!$C:$C, $C2, KASA!$B:$B, "MAL İADE") -> 0 | H2: =SUMIFS(KASA!$K:$K, KASA!$C:$C, $C2, KASA!$B:$B, "MAL İADE") + SUMIFS(KASA!$Q:$Q, KASA!$C:$C, $C2, KASA!$B:$B, "MAL İADE") -> 0 | I2: =F2+G2 -> 26.466581 | J2: =E2*F2 -> 8733.9717 | K2: =SUMIFS(KASA!$Q:$Q, KASA!$C:$C, $C2, KASA!$B:$B, "MAL SATIŞI") + SUMIFS(KASA!$Q:$Q, KASA!$C:$C, $C2, KASA!$B:$B, "ÜRETİM ÇIKIŞ") -> 10098.196 | L2: =SUMIFS(KASA!$K:$K, KASA!$C:$C, $C2, KASA!$B:$B, "MAL SATIŞI") + SUMIFS(KASA!$K:$K, KASA!$C:$C, $C2, KASA!$B:$B, "ÜRETİM ÇIKIŞ") -> 5868.9662 | M2: =K2+L2 -> 15967.162 | N2: =M2-J2 -> 7233.1906 | O2: =IFERROR(((M2-J2)/J2),0) -> 0.82816741 | P2: =M2/F2 -> 603.29524 | Q2: =D2-F2-G2 -> 23.533419 | R2: =Q2*E2 -> 7766.0283 | S2: =D2*E2 -> 16500 | T2: =2.056+24.836+2.636-0.156 -> 29.372 | U2: =Q2-T2 -> -5.8385808 | V2: =SUMIF(KASA!$C$2:$C$9980, C2, KASA!$T$2:$T$9980) -> 23.533419 | W2: =SUMIF(KASA!$C$2:$C$9980, C2, KASA!$U$2:$U$9980) -> 8001.3625 | X2: =V2-G2 -> 23.533419 | Y2: =W2-H2 -> 8001.3625 | Z2: =SUMIF(KASA!$C$2:$C$9980, C2, KASA!$V$2:$V$9980) -> 16500 | AA2: =Z2-W2 -> 8498.6375
C3: KİMYON ÇEKİLMİŞ | D3: =SUMIFS(KASA!$I:$I, KASA!$C:$C, $C3, KASA!$B:$B, "MAL ALIMI") + SUMIFS(KASA!$I:$I, KASA!$C:$C, $C3, KASA!$B:$B, "ÜRETİM GİRİŞ") -> 50 | E3: =Z3/D3 -> 185 | F3: =SUMIFS(KASA!$I:$I, KASA!$C:$C, $C3, KASA!$B:$B, "MAL SATIŞI") + SUMIFS(KASA!$I:$I, KASA!$C:$C, $C3, KASA!$B:$B, "ÜRETİM ÇIKIŞ") -> 20.486713 | G3: =SUMIFS(KASA!$I:$I, KASA!$C:$C, $C3, KASA!$B:$B, "MAL İADE") -> 0 | H3: =SUMIFS(KASA!$K:$K, KASA!$C:$C, $C3, KASA!$B:$B, "MAL İADE") + SUMIFS(KASA!$Q:$Q, KASA!$C:$C, $C3, KASA!$B:$B, "MAL İADE") -> 0 | I3: =F3+G3 -> 20.486713 | J3: =E3*F3 -> 3790.0418 | K3: =SUMIFS(KASA!$Q:$Q, KASA!$C:$C, $C3, KASA!$B:$B, "MAL SATIŞI") + SUMIFS(KASA!$Q:$Q, KASA!$C:$C, $C3, KASA!$B:$B, "ÜRETİM ÇIKIŞ") -> 5409.605 | L3: =SUMIFS(KASA!$K:$K, KASA!$C:$C, $C3, KASA!$B:$B, "MAL SATIŞI") + SUMIFS(KASA!$K:$K, KASA!$C:$C, $C3, KASA!$B:$B, "ÜRETİM ÇIKIŞ") -> 1890.78 | M3: =K3+L3 -> 7300.385 | N3: =M3-J3 -> 3510.3432 | O3: =IFERROR(((M3-J3)/J3),0) -> 0.92620169 | P3: =M3/F3 -> 356.34731 | Q3: =D3-F3-G3 -> 29.513287 | R3: =Q3*E3 -> 5459.9582 | S3: =D3*E3 -> 9250 | T3: 34.846 | U3: =Q3-T3 -> -5.3327127 | V3: =SUMIF(KASA!$C$2:$C$9980, C3, KASA!$T$2:$T$9980) -> 29.513287 | W3: =SUMIF(KASA!$C$2:$C$9980, C3, KASA!$U$2:$U$9980) -> 5767.2588 | X3: =V3-G3 -> 29.513287 | Y3: =W3-H3 -> 5767.2588 | Z3: =SUMIF(KASA!$C$2:$C$9980, C3, KASA!$V$2:$V$9980) -> 9250 | AA3: =Z3-W3 -> 3482.7412
C4: KÖFTE BAHARATI (YEDİTÜRLÜ) | D4: =SUMIFS(KASA!$I:$I, KASA!$C:$C, $C4, KASA!$B:$B, "MAL ALIMI") + SUMIFS(KASA!$I:$I, KASA!$C:$C, $C4, KASA!$B:$B, "ÜRETİM GİRİŞ") -> 15 | E4: {=IFERROR(AVERAGE(IF((KASA!$C$2:$C$9980=$C4)*((KASA!$B$2:$B$9980="MAL ALIMI")+(KASA!$B$2:$B$9980="ÜRETİM GİRİŞ")),KASA!$J$2:$J$9980)),0)} -> 185 | F4: =SUMIFS(KASA!$I:$I, KASA!$C:$C, $C4, KASA!$B:$B, "MAL SATIŞI") + SUMIFS(KASA!$I:$I, KASA!$C:$C, $C4, KASA!$B:$B, "ÜRETİM ÇIKIŞ") -> 4.0523713 | G4: =SUMIFS(KASA!$I:$I, KASA!$C:$C, $C4, KASA!$B:$B, "MAL İADE") -> 0 | H4: =SUMIFS(KASA!$K:$K, KASA!$C:$C, $C4, KASA!$B:$B, "MAL İADE") + SUMIFS(KASA!$Q:$Q, KASA!$C:$C, $C4, KASA!$B:$B, "MAL İADE") -> 0 | I4: =F4+G4 -> 4.0523713 | J4: =E4*F4 -> 749.68869 | K4: =SUMIFS(KASA!$Q:$Q, KASA!$C:$C, $C4, KASA!$B:$B, "MAL SATIŞI") + SUMIFS(KASA!$Q:$Q, KASA!$C:$C, $C4, KASA!$B:$B, "ÜRETİM ÇIKIŞ") -> 1059 | L4: =SUMIFS(KASA!$K:$K, KASA!$C:$C, $C4, KASA!$B:$B, "MAL SATIŞI") + SUMIFS(KASA!$K:$K, KASA!$C:$C, $C4, KASA!$B:$B, "ÜRETİM ÇIKIŞ") -> 544.1 | M4: =K4+L4 -> 1603.1 | N4: =M4-J4 -> 853.41131 | O4: =IFERROR(((M4-J4)/J4),0) -> 1.1383543 | P4: =M4/F4 -> 395.59554 | Q4: =D4-F4-G4 -> 10.947629 | R4: =Q4*E4 -> 2025.3113 | S4: =D4*E4 -> 2775 | T4: 13.59 | U4: =Q4-T4 -> -2.6423713 | V4: =SUMIF(KASA!$C$2:$C$9980, C4, KASA!$T$2:$T$9980) -> 10.947629 | W4: =SUMIF(KASA!$C$2:$C$9980, C4, KASA!$U$2:$U$9980) -> 2020.5732 | X4: =V4-G4 -> 10.947629 | Y4: =W4-H4 -> 2020.5732 | Z4: =SUMIF(KASA!$C$2:$C$9980, C4, KASA!$V$2:$V$9980) -> 2750 | AA4: =Z4-W4 -> 729.42683
C5: NANE İRİ | D5: =SUMIFS(KASA!$I:$I, KASA!$C:$C, $C5, KASA!$B:$B, "MAL ALIMI") + SUMIFS(KASA!$I:$I, KASA!$C:$C, $C5, KASA!$B:$B, "ÜRETİM GİRİŞ") -> 50 | E5: {=IFERROR(AVERAGE(IF((KASA!$C$2:$C$9980=$C5)*((KASA!$B$2:$B$9980="MAL ALIMI")+(KASA!$B$2:$B$9980="ÜRETİM GİRİŞ")),KASA!$J$2:$J$9980)),0)} -> 127.5 | F5: =SUMIFS(KASA!$I:$I, KASA!$C:$C, $C5, KASA!$B:$B, "MAL SATIŞI") + SUMIFS(KASA!$I:$I, KASA!$C:$C, $C5, KASA!$B:$B, "ÜRETİM ÇIKIŞ") -> 21.381971 | G5: =SUMIFS(KASA!$I:$I, KASA!$C:$C, $C5, KASA!$B:$B, "MAL İADE") -> 0 | H5: =SUMIFS(KASA!$K:$K, KASA!$C:$C, $C5, KASA!$B:$B, "MAL İADE") + SUMIFS(KASA!$Q:$Q, KASA!$C:$C, $C5, KASA!$B:$B, "MAL İADE") -> 0 | I5: =F5+G5 -> 21.381971 | J5: =E5*F5 -> 2726.2014 | K5: =SUMIFS(KASA!$Q:$Q, KASA!$C:$C, $C5, KASA!$B:$B, "MAL SATIŞI") + SUMIFS(KASA!$Q:$Q, KASA!$C:$C, $C5, KASA!$B:$B, "ÜRETİM ÇIKIŞ") -> 5975.47 | L5: =SUMIFS(KASA!$K:$K, KASA!$C:$C, $C5, KASA!$B:$B, "MAL SATIŞI") + SUMIFS(KASA!$K:$K, KASA!$C:$C, $C5, KASA!$B:$B, "ÜRETİM ÇIKIŞ") -> 1819 | M5: =K5+L5 -> 7794.47 | N5: =M5-J5 -> 5068.2686 | O5: =IFERROR(((M5-J5)/J5),0) -> 1.8590955 | P5: =M5/F5 -> 364.53467 | Q5: =D5-F5-G5 -> 28.618029 | R5: =Q5*E5 -> 3648.7986 | S5: =D5*E5 -> 6375 | T5: 33.53 | U5: =Q5-T5 -> -4.9119714 | V5: =SUMIF(KASA!$C$2:$C$9980, C5, KASA!$T$2:$T$9980) -> 28.618029 | W5: =SUMIF(KASA!$C$2:$C$9980, C5, KASA!$U$2:$U$9980) -> 3702.2536 | X5: =V5-G5 -> 28.618029 | Y5: =W5-H5 -> 3702.2536 | Z5: =SUMIF(KASA!$C$2:$C$9980, C5, KASA!$V$2:$V$9980) -> 6375 | AA5: =Z5-W5 -> 2672.7464
C6: SUMAK | D6: =SUMIFS(KASA!$I:$I, KASA!$C:$C, $C6, KASA!$B:$B, "MAL ALIMI") + SUMIFS(KASA!$I:$I, KASA!$C:$C, $C6, KASA!$B:$B, "ÜRETİM GİRİŞ") -> 25 | E6: {=IFERROR(AVERAGE(IF((KASA!$C$2:$C$9980=$C6)*((KASA!$B$2:$B$9980="MAL ALIMI")+(KASA!$B$2:$B$9980="ÜRETİM GİRİŞ")),KASA!$J$2:$J$9980)),0)} -> 200 | F6: =SUMIFS(KASA!$I:$I, KASA!$C:$C, $C6, KASA!$B:$B, "MAL SATIŞI") + SUMIFS(KASA!$I:$I, KASA!$C:$C, $C6, KASA!$B:$B, "ÜRETİM ÇIKIŞ") -> 25.313714 | G6: =SUMIFS(KASA!$I:$I, KASA!$C:$C, $C6, KASA!$B:$B, "MAL İADE") -> 0 | H6: =SUMIFS(KASA!$K:$K, KASA!$C:$C, $C6, KASA!$B:$B, "MAL İADE") + SUMIFS(KASA!$Q:$Q, KASA!$C:$C, $C6, KASA!$B:$B, "MAL İADE") -> 0 | I6: =F6+G6 -> 25.313714 | J6: =E6*F6 -> 5062.7429 | K6: =SUMIFS(KASA!$Q:$Q, KASA!$C:$C, $C6, KASA!$B:$B, "MAL SATIŞI") + SUMIFS(KASA!$Q:$Q, KASA!$C:$C, $C6, KASA!$B:$B, "ÜRETİM ÇIKIŞ") -> 6738 | L6: =SUMIFS(KASA!$K:$K, KASA!$C:$C, $C6, KASA!$B:$B, "MAL SATIŞI") + SUMIFS(KASA!$K:$K, KASA!$C:$C, $C6, KASA!$B:$B, "ÜRETİM ÇIKIŞ") -> 4211.46 | M6: =K6+L6 -> 10949.46 | N6: =M6-J6 -> 5886.7171 | O6: =IFERROR(((M6-J6)/J6),0) -> 1.1627525 | P6: =M6/F6 -> 432.55051 | Q6: =D6-F6-G6 -> -0.31371429 | R6: =Q6*E6 -> -62.742857 | S6: =D6*E6 -> 5000 | T6: 4.534 | U6: =Q6-T6 -> -4.8477143 | V6: =SUMIF(KASA!$C$2:$C$9980, C6, KASA!$T$2:$T$9980) -> 0 | W6: =SUMIF(KASA!$C$2:$C$9980, C6, KASA!$U$2:$U$9980) -> 0 | X6: =V6-G6 -> 0 | Y6: =W6-H6 -> 0 | Z6: =SUMIF(KASA!$C$2:$C$9980, C6, KASA!$V$2:$V$9980) -> 5000 | AA6: =Z6-W6 -> 5000
C7: KEKİK LÜX | D7: =SUMIFS(KASA!$I:$I, KASA!$C:$C, $C7, KASA!$B:$B, "MAL ALIMI") + SUMIFS(KASA!$I:$I, KASA!$C:$C, $C7, KASA!$B:$B, "ÜRETİM GİRİŞ") -> 20 | E7: {=IFERROR(AVERAGE(IF((KASA!$C$2:$C$9980=$C7)*((KASA!$B$2:$B$9980="MAL ALIMI")+(KASA!$B$2:$B$9980="ÜRETİM GİRİŞ")),KASA!$J$2:$J$9980)),0)} -> 520 | F7: =SUMIFS(KASA!$I:$I, KASA!$C:$C, $C7, KASA!$B:$B, "MAL SATIŞI") + SUMIFS(KASA!$I:$I, KASA!$C:$C, $C7, KASA!$B:$B, "ÜRETİM ÇIKIŞ") -> 11.428463 | G7: =SUMIFS(KASA!$I:$I, KASA!$C:$C, $C7, KASA!$B:$B, "MAL İADE") -> 0 | H7: =SUMIFS(KASA!$K:$K, KASA!$C:$C, $C7, KASA!$B:$B, "MAL İADE") + SUMIFS(KASA!$Q:$Q, KASA!$C:$C, $C7, KASA!$B:$B, "MAL İADE") -> 0 | I7: =F7+G7 -> 11.428463 | J7: =E7*F7 -> 5942.8005 | K7: =SUMIFS(KASA!$Q:$Q, KASA!$C:$C, $C7, KASA!$B:$B, "MAL SATIŞI") + SUMIFS(KASA!$Q:$Q, KASA!$C:$C, $C7, KASA!$B:$B, "ÜRETİM ÇIKIŞ") -> 5451.59 | L7: =SUMIFS(KASA!$K:$K, KASA!$C:$C, $C7, KASA!$B:$B, "MAL SATIŞI") + SUMIFS(KASA!$K:$K, KASA!$C:$C, $C7, KASA!$B:$B, "ÜRETİM ÇIKIŞ") -> 3045.613 | M7: =K7+L7 -> 8497.203 | N7: =M7-J7 -> 2554.4025 | O7: =IFERROR(((M7-J7)/J7),0) -> 0.42983143 | P7: =M7/F7 -> 743.51234 | Q7: =D7-F7-G7 -> 8.5715374 | R7: =Q7*E7 -> 4457.1995 | S7: =D7*E7 -> 10400 | T7: 2.01 | U7: =Q7-T7 -> 6.5615374 | V7: =SUMIF(KASA!$C$2:$C$9980, C7, KASA!$T$2:$T$9980) -> 8.5715374 | W7: =SUMIF(KASA!$C$2:$C$9980, C7, KASA!$U$2:$U$9980) -> 5314.3532 | X7: =V7-G7 -> 8.5715374 | Y7: =W7-H7 -> 5314.3532 | Z7: =SUMIF(KASA!$C$2:$C$9980, C7, KASA!$V$2:$V$9980) -> 10400 | AA7: =Z7-W7 -> 5085.6468
C8: İPEK BİBER | D8: =SUMIFS(KASA!$I:$I, KASA!$C:$C, $C8, KASA!$B:$B, "MAL ALIMI") + SUMIFS(KASA!$I:$I, KASA!$C:$C, $C8, KASA!$B:$B, "ÜRETİM GİRİŞ") -> 65 | E8: {=IFERROR(AVERAGE(IF((KASA!$C$2:$C$9980=$C8)*((KASA!$B$2:$B$9980="MAL ALIMI")+(KASA!$B$2:$B$9980="ÜRETİM GİRİŞ")),KASA!$J$2:$J$9980)),0)} -> 265 | F8: =SUMIFS(KASA!$I:$I, KASA!$C:$C, $C8, KASA!$B:$B, "MAL SATIŞI") + SUMIFS(KASA!$I:$I, KASA!$C:$C, $C8, KASA!$B:$B, "ÜRETİM ÇIKIŞ") -> 30.97 | G8: =SUMIFS(KASA!$I:$I, KASA!$C:$C, $C8, KASA!$B:$B, "MAL İADE") -> 0 | H8: =SUMIFS(KASA!$K:$K, KASA!$C:$C, $C8, KASA!$B:$B, "MAL İADE") + SUMIFS(KASA!$Q:$Q, KASA!$C:$C, $C8, KASA!$B:$B, "MAL İADE") -> 0 | I8: =F8+G8 -> 30.97 | J8: =E8*F8 -> 8207.05 | K8: =SUMIFS(KASA!$Q:$Q, KASA!$C:$C, $C8, KASA!$B:$B, "MAL SATIŞI") + SUMIFS(KASA!$Q:$Q, KASA!$C:$C, $C8, KASA!$B:$B, "ÜRETİM ÇIKIŞ") -> 8073.52 | L8: =SUMIFS(KASA!$K:$K, KASA!$C:$C, $C8, KASA!$B:$B, "MAL SATIŞI") + SUMIFS(KASA!$K:$K, KASA!$C:$C, $C8, KASA!$B:$B, "ÜRETİM ÇIKIŞ") -> 6486.95 | M8: =K8+L8 -> 14560.47 | N8: =M8-J8 -> 6353.42 | O8: =IFERROR(((M8-J8)/J8),0) -> 0.77414174 | P8: =M8/F8 -> 470.14756 | Q8: =D8-F8-G8 -> 34.03 | R8: =Q8*E8 -> 9017.95 | S8: =D8*E8 -> 17225 | T8: 20.056 | U8: =Q8-T8 -> 13.974 | V8: =SUMIF(KASA!$C$2:$C$9980, C8, KASA!$T$2:$T$9980) -> 34.03 | W8: =SUMIF(KASA!$C$2:$C$9980, C8, KASA!$U$2:$U$9980) -> 9347.8 | X8: =V8-G8 -> 34.03 | Y8: =W8-H8 -> 9347.8 | Z8: =SUMIF(KASA!$C$2:$C$9980, C8, KASA!$V$2:$V$9980) -> 17150 | AA8: =Z8-W8 -> 7802.2
C9: İSOT | D9: =SUMIFS(KASA!$I:$I, KASA!$C:$C, $C9, KASA!$B:$B, "MAL ALIMI") + SUMIFS(KASA!$I:$I, KASA!$C:$C, $C9, KASA!$B:$B, "ÜRETİM GİRİŞ") -> 50 | E9: {=IFERROR(AVERAGE(IF((KASA!$C$2:$C$9980=$C9)*((KASA!$B$2:$B$9980="MAL ALIMI")+(KASA!$B$2:$B$9980="ÜRETİM GİRİŞ")),KASA!$J$2:$J$9980)),0)} -> 180 | F9: =SUMIFS(KASA!$I:$I, KASA!$C:$C, $C9, KASA!$B:$B, "MAL SATIŞI") + SUMIFS(KASA!$I:$I, KASA!$C:$C, $C9, KASA!$B:$B, "ÜRETİM ÇIKIŞ") -> 31.508263 | G9: =SUMIFS(KASA!$I:$I, KASA!$C:$C, $C9, KASA!$B:$B, "MAL İADE") -> 0 | H9: =SUMIFS(KASA!$K:$K, KASA!$C:$C, $C9, KASA!$B:$B, "MAL İADE") + SUMIFS(KASA!$Q:$Q, KASA!$C:$C, $C9, KASA!$B:$B, "MAL İADE") -> 0 | I9: =F9+G9 -> 31.508263 | J9: =E9*F9 -> 5671.4874 | K9: =SUMIFS(KASA!$Q:$Q, KASA!$C:$C, $C9, KASA!$B:$B, "MAL SATIŞI") + SUMIFS(KASA!$Q:$Q, KASA!$C:$C, $C9, KASA!$B:$B, "ÜRETİM ÇIKIŞ") -> 5039.28 | L9: =SUMIFS(KASA!$K:$K, KASA!$C:$C, $C9, KASA!$B:$B, "MAL SATIŞI") + SUMIFS(KASA!$K:$K, KASA!$C:$C, $C9, KASA!$B:$B, "ÜRETİM ÇIKIŞ") -> 5229.065 | M9: =K9+L9 -> 10268.345 | N9: =M9-J9 -> 4596.8576 | O9: =IFERROR(((M9-J9)/J9),0) -> 0.81052065 | P9: =M9/F9 -> 325.89372 | Q9: =D9-F9-G9 -> 18.491737 | R9: =Q9*E9 -> 3328.5126 | S9: =D9*E9 -> 9000 | T9: 27.9 | U9: =Q9-T9 -> -9.4082632 | V9: =SUMIF(KASA!$C$2:$C$9980, C9, KASA!$T$2:$T$9980) -> 18.491737 | W9: =SUMIF(KASA!$C$2:$C$9980, C9, KASA!$U$2:$U$9980) -> 3328.5126 | X9: =V9-G9 -> 18.491737 | Y9: =W9-H9 -> 3328.5126 | Z9: =SUMIF(KASA!$C$2:$C$9980, C9, KASA!$V$2:$V$9980) -> 9000 | AA9: =Z9-W9 -> 5671.4874
C10: TOZ BİBER - ACI | D10: =SUMIFS(KASA!$I:$I, KASA!$C:$C, $C10, KASA!$B:$B, "MAL ALIMI") + SUMIFS(KASA!$I:$I, KASA!$C:$C, $C10, KASA!$B:$B, "ÜRETİM GİRİŞ") -> 25 | E10: {=IFERROR(AVERAGE(IF((KASA!$C$2:$C$9980=$C10)*((KASA!$B$2:$B$9980="MAL ALIMI")+(KASA!$B$2:$B$9980="ÜRETİM GİRİŞ")),KASA!$J$2:$J$9980)),0)} -> 160 | F10: =SUMIFS(KASA!$I:$I, KASA!$C:$C, $C10, KASA!$B:$B, "MAL SATIŞI") + SUMIFS(KASA!$I:$I, KASA!$C:$C, $C10, KASA!$B:$B, "ÜRETİM ÇIKIŞ") -> 5.6349054 | G10: =SUMIFS(KASA!$I:$I, KASA!$C:$C, $C10, KASA!$B:$B, "MAL İADE") -> 16.2 | H10: =SUMIFS(KASA!$K:$K, KASA!$C:$C, $C10, KASA!$B:$B, "MAL İADE") + SUMIFS(KASA!$Q:$Q, KASA!$C:$C, $C10, KASA!$B:$B, "MAL İADE") -> 2592 | I10: =F10+G10 -> 21.834905 | J10: =E10*F10 -> 901.58486 | K10: =SUMIFS(KASA!$Q:$Q, KASA!$C:$C, $C10, KASA!$B:$B, "MAL SATIŞI") + SUMIFS(KASA!$Q:$Q, KASA!$C:$C, $C10, KASA!$B:$B, "ÜRETİM ÇIKIŞ") -> 1473.31 | L10: =SUMIFS(KASA!$K:$K, KASA!$C:$C, $C10, KASA!$B:$B, "MAL SATIŞI") + SUMIFS(KASA!$K:$K, KASA!$C:$C, $C10, KASA!$B:$B, "ÜRETİM ÇIKIŞ") -> 501.37 | M10: =K10+L10 -> 1974.68 | N10: =M10-J10 -> 1073.0951 | O10: =IFERROR(((M10-J10)/J10),0) -> 1.190232 | P10: =M10/F10 -> 350.43712 | Q10: =D10-F10-G10 -> 3.1650946 | R10: =Q10*E10 -> 506.41514 | S10: =D10*E10 -> 4000 | T10: 5.436 | U10: =Q10-T10 -> -2.2709054 | V10: =SUMIF(KASA!$C$2:$C$9980, C10, KASA!$T$2:$T$9980) -> 19.365095 | W10: =SUMIF(KASA!$C$2:$C$9980, C10, KASA!$U$2:$U$9980) -> 3098.4151 | X10: =V10-G10 -> 3.1650946 | Y10: =W10-H10 -> 506.41514 | Z10: =SUMIF(KASA!$C$2:$C$9980, C10, KASA!$V$2:$V$9980) -> 4000 | AA10: =Z10-W10 -> 901.58486
C11: EVLİK BİBER | D11: =SUMIFS(KASA!$I:$I, KASA!$C:$C, $C11, KASA!$B:$B, "MAL ALIMI") + SUMIFS(KASA!$I:$I, KASA!$C:$C, $C11, KASA!$B:$B, "ÜRETİM GİRİŞ") -> 75 | E11: {=IFERROR(AVERAGE(IF((KASA!$C$2:$C$9980=$C11)*((KASA!$B$2:$B$9980="MAL ALIMI")+(KASA!$B$2:$B$9980="ÜRETİM GİRİŞ")),KASA!$J$2:$J$9980)),0)} -> 186.66667 | F11: =SUMIFS(KASA!$I:$I, KASA!$C:$C, $C11, KASA!$B:$B, "MAL SATIŞI") + SUMIFS(KASA!$I:$I, KASA!$C:$C, $C11, KASA!$B:$B, "ÜRETİM ÇIKIŞ") -> 54.567077 | G11: =SUMIFS(KASA!$I:$I, KASA!$C:$C, $C11, KASA!$B:$B, "MAL İADE") -> 0 | H11: =SUMIFS(KASA!$K:$K, KASA!$C:$C, $C11, KASA!$B:$B, "MAL İADE") + SUMIFS(KASA!$Q:$Q, KASA!$C:$C, $C11, KASA!$B:$B, "MAL İADE") -> 0 | I11: =F11+G11 -> 54.567077 | J11: =E11*F11 -> 10185.854 | K11: =SUMIFS(KASA!$Q:$Q, KASA!$C:$C, $C11, KASA!$B:$B, "MAL SATIŞI") + SUMIFS(KASA!$Q:$Q, KASA!$C:$C, $C11, KASA!$B:$B, "ÜRETİM ÇIKIŞ") -> 8181.596 | L11: =SUMIFS(KASA!$K:$K, KASA!$C:$C, $C11, KASA!$B:$B, "MAL SATIŞI") + SUMIFS(KASA!$K:$K, KASA!$C:$C, $C11, KASA!$B:$B, "ÜRETİM ÇIKIŞ") -> 9330.86 | M11: =K11+L11 -> 17512.456 | N11: =M11-J11 -> 7326.6016 | O11: =IFERROR(((M11-J11)/J11),0) -> 0.7192918 | P11: =M11/F11 -> 320.93447 | Q11: =D11-F11-G11 -> 20.432923 | R11: =Q11*E11 -> 3814.1456 | S11: =D11*E11 -> 14000 | T11: 25.25 | U11: =Q11-T11 -> -4.8170772 | V11: =SUMIF(KASA!$C$2:$C$9980, C11, KASA!$T$2:$T$9980) -> 20.432923 | W11: =SUMIF(KASA!$C$2:$C$9980, C11, KASA!$U$2:$U$9980) -> 4290.9138 | X11: =V11-G11 -> 20.432923 | Y11: =W11-H11 -> 4290.9138 | Z11: =SUMIF(KASA!$C$2:$C$9980, C11, KASA!$V$2:$V$9980) -> 14000 | AA11: =Z11-W11 -> 9709.0862
